[2023-09-23T14:03:13.218+0000] {taskinstance.py:1157} INFO - Dependencies all met for dep_context=non-requeueable deps ti=<TaskInstance: tests_dag.test_db_conns manual__2023-09-23T14:03:05.419471+00:00 [queued]>
[2023-09-23T14:03:13.241+0000] {taskinstance.py:1157} INFO - Dependencies all met for dep_context=requeueable deps ti=<TaskInstance: tests_dag.test_db_conns manual__2023-09-23T14:03:05.419471+00:00 [queued]>
[2023-09-23T14:03:13.242+0000] {taskinstance.py:1359} INFO - Starting attempt 1 of 1
[2023-09-23T14:03:13.362+0000] {taskinstance.py:1380} INFO - Executing <Task(BashOperator): test_db_conns> on 2023-09-23 14:03:05.419471+00:00
[2023-09-23T14:03:13.394+0000] {standard_task_runner.py:57} INFO - Started process 816 to run task
[2023-09-23T14:03:13.414+0000] {standard_task_runner.py:84} INFO - Running: ['***', 'tasks', 'run', 'tests_dag', 'test_db_conns', 'manual__2023-09-23T14:03:05.419471+00:00', '--job-id', '20', '--raw', '--subdir', 'DAGS_FOLDER/test_dag.py', '--cfg-path', '/tmp/tmp268ayclt']
[2023-09-23T14:03:13.427+0000] {standard_task_runner.py:85} INFO - Job 20: Subtask test_db_conns
[2023-09-23T14:03:13.623+0000] {task_command.py:415} INFO - Running <TaskInstance: tests_dag.test_db_conns manual__2023-09-23T14:03:05.419471+00:00 [running]> on host 4ef300bfa8d2
[2023-09-23T14:03:13.818+0000] {taskinstance.py:1660} INFO - Exporting env vars: AIRFLOW_CTX_DAG_OWNER='***' AIRFLOW_CTX_DAG_ID='tests_dag' AIRFLOW_CTX_TASK_ID='test_db_conns' AIRFLOW_CTX_EXECUTION_DATE='2023-09-23T14:03:05.419471+00:00' AIRFLOW_CTX_TRY_NUMBER='1' AIRFLOW_CTX_DAG_RUN_ID='manual__2023-09-23T14:03:05.419471+00:00'
[2023-09-23T14:03:13.822+0000] {subprocess.py:63} INFO - Tmp dir root location: /tmp
[2023-09-23T14:03:13.825+0000] {subprocess.py:75} INFO - Running command: ['/bin/bash', '-c', 'pytest /opt/***/dags/dag_scripts/tests/test_db_connections.py']
[2023-09-23T14:03:13.842+0000] {subprocess.py:86} INFO - Output:
[2023-09-23T14:03:15.013+0000] {subprocess.py:93} INFO - ============================= test session starts ==============================
[2023-09-23T14:03:15.013+0000] {subprocess.py:93} INFO - platform linux -- Python 3.8.18, pytest-7.4.2, pluggy-1.3.0
[2023-09-23T14:03:15.014+0000] {subprocess.py:93} INFO - rootdir: /opt/***/dags/dag_scripts/tests
[2023-09-23T14:03:15.014+0000] {subprocess.py:93} INFO - plugins: anyio-4.0.0
[2023-09-23T14:03:15.014+0000] {subprocess.py:93} INFO - collected 7 items
[2023-09-23T14:03:15.014+0000] {subprocess.py:93} INFO - 
[2023-09-23T14:03:15.383+0000] {subprocess.py:93} INFO - ../../opt/***/dags/dag_scripts/tests/test_db_connections.py ......F  [100%]
[2023-09-23T14:03:15.383+0000] {subprocess.py:93} INFO - 
[2023-09-23T14:03:15.383+0000] {subprocess.py:93} INFO - =================================== FAILURES ===================================
[2023-09-23T14:03:15.384+0000] {subprocess.py:93} INFO - ____________________________ test_redis_connection _____________________________
[2023-09-23T14:03:15.384+0000] {subprocess.py:93} INFO - 
[2023-09-23T14:03:15.384+0000] {subprocess.py:93} INFO -     def test_redis_connection():
[2023-09-23T14:03:15.384+0000] {subprocess.py:93} INFO -         """Test that the user can connect to the Redis database"""
[2023-09-23T14:03:15.384+0000] {subprocess.py:93} INFO -         redis_conn = db_connection_funcs.get_redis_connection()
[2023-09-23T14:03:15.385+0000] {subprocess.py:93} INFO -         response = redis_conn.ping()
[2023-09-23T14:03:15.385+0000] {subprocess.py:93} INFO - >       assert response=="PONG"
[2023-09-23T14:03:15.385+0000] {subprocess.py:93} INFO - E       AssertionError: assert True == 'PONG'
[2023-09-23T14:03:15.385+0000] {subprocess.py:93} INFO - 
[2023-09-23T14:03:15.386+0000] {subprocess.py:93} INFO - /opt/***/dags/dag_scripts/tests/test_db_connections.py:71: AssertionError
[2023-09-23T14:03:15.386+0000] {subprocess.py:93} INFO - =========================== short test summary info ============================
[2023-09-23T14:03:15.386+0000] {subprocess.py:93} INFO - FAILED ../../opt/***/dags/dag_scripts/tests/test_db_connections.py::test_redis_connection
[2023-09-23T14:03:15.387+0000] {subprocess.py:93} INFO - ========================= 1 failed, 6 passed in 0.90s ==========================
[2023-09-23T14:03:15.916+0000] {subprocess.py:97} INFO - Command exited with return code 1
[2023-09-23T14:03:15.934+0000] {taskinstance.py:1935} ERROR - Task failed with exception
Traceback (most recent call last):
  File "/home/airflow/.local/lib/python3.8/site-packages/airflow/operators/bash.py", line 210, in execute
    raise AirflowException(
airflow.exceptions.AirflowException: Bash command failed. The command returned a non-zero exit code 1.
[2023-09-23T14:03:15.943+0000] {taskinstance.py:1398} INFO - Marking task as FAILED. dag_id=tests_dag, task_id=test_db_conns, execution_date=20230923T140305, start_date=20230923T140313, end_date=20230923T140315
[2023-09-23T14:03:15.972+0000] {standard_task_runner.py:104} ERROR - Failed to execute job 20 for task test_db_conns (Bash command failed. The command returned a non-zero exit code 1.; 816)
[2023-09-23T14:03:15.992+0000] {local_task_job_runner.py:228} INFO - Task exited with return code 1
[2023-09-23T14:03:16.047+0000] {taskinstance.py:2776} INFO - 0 downstream tasks scheduled from follow-on schedule check
