[2023-09-20T11:21:09.757+0000] {taskinstance.py:1157} INFO - Dependencies all met for dep_context=non-requeueable deps ti=<TaskInstance: main_dag.run_dbt manual__2023-09-20T11:20:39.886608+00:00 [queued]>
[2023-09-20T11:21:09.769+0000] {taskinstance.py:1157} INFO - Dependencies all met for dep_context=requeueable deps ti=<TaskInstance: main_dag.run_dbt manual__2023-09-20T11:20:39.886608+00:00 [queued]>
[2023-09-20T11:21:09.770+0000] {taskinstance.py:1359} INFO - Starting attempt 1 of 1
[2023-09-20T11:21:09.799+0000] {taskinstance.py:1380} INFO - Executing <Task(BashOperator): run_dbt> on 2023-09-20 11:20:39.886608+00:00
[2023-09-20T11:21:09.805+0000] {standard_task_runner.py:57} INFO - Started process 85 to run task
[2023-09-20T11:21:09.809+0000] {standard_task_runner.py:84} INFO - Running: ['***', 'tasks', 'run', 'main_dag', 'run_dbt', 'manual__2023-09-20T11:20:39.886608+00:00', '--job-id', '6', '--raw', '--subdir', 'DAGS_FOLDER/main_dag.py', '--cfg-path', '/tmp/tmp8pixk01f']
[2023-09-20T11:21:09.986+0000] {standard_task_runner.py:85} INFO - Job 6: Subtask run_dbt
[2023-09-20T11:21:10.039+0000] {task_command.py:415} INFO - Running <TaskInstance: main_dag.run_dbt manual__2023-09-20T11:20:39.886608+00:00 [running]> on host 0cbc793eb09c
[2023-09-20T11:21:10.165+0000] {taskinstance.py:1660} INFO - Exporting env vars: AIRFLOW_CTX_DAG_OWNER='***' AIRFLOW_CTX_DAG_ID='main_dag' AIRFLOW_CTX_TASK_ID='run_dbt' AIRFLOW_CTX_EXECUTION_DATE='2023-09-20T11:20:39.886608+00:00' AIRFLOW_CTX_TRY_NUMBER='1' AIRFLOW_CTX_DAG_RUN_ID='manual__2023-09-20T11:20:39.886608+00:00'
[2023-09-20T11:21:10.167+0000] {subprocess.py:63} INFO - Tmp dir root location: /tmp
[2023-09-20T11:21:10.168+0000] {subprocess.py:75} INFO - Running command: ['/bin/bash', '-c', 'dbt run --profiles-dir /.dbt --project-dir /app']
[2023-09-20T11:21:10.181+0000] {subprocess.py:86} INFO - Output:
[2023-09-20T11:21:15.386+0000] {subprocess.py:93} INFO - [0m11:21:15  Encountered an error:
[2023-09-20T11:21:15.387+0000] {subprocess.py:93} INFO - [Errno 13] Permission denied: '/app/logs/dbt.log'
[2023-09-20T11:21:15.389+0000] {subprocess.py:93} INFO - [0m11:21:15  Traceback (most recent call last):
[2023-09-20T11:21:15.389+0000] {subprocess.py:93} INFO -   File "/home/***/.local/lib/python3.8/site-packages/dbt/cli/requires.py", line 86, in wrapper
[2023-09-20T11:21:15.390+0000] {subprocess.py:93} INFO -     result, success = func(*args, **kwargs)
[2023-09-20T11:21:15.390+0000] {subprocess.py:93} INFO -   File "/home/***/.local/lib/python3.8/site-packages/dbt/cli/requires.py", line 47, in wrapper
[2023-09-20T11:21:15.390+0000] {subprocess.py:93} INFO -     setup_event_logger(flags=flags, callbacks=callbacks)
[2023-09-20T11:21:15.390+0000] {subprocess.py:93} INFO -   File "/home/***/.local/lib/python3.8/site-packages/dbt/events/functions.py", line 64, in setup_event_logger
[2023-09-20T11:21:15.391+0000] {subprocess.py:93} INFO -     EVENT_MANAGER.add_logger(
[2023-09-20T11:21:15.391+0000] {subprocess.py:93} INFO -   File "/home/***/.local/lib/python3.8/site-packages/dbt/events/eventmgr.py", line 211, in add_logger
[2023-09-20T11:21:15.391+0000] {subprocess.py:93} INFO -     else _TextLogger(self, config)
[2023-09-20T11:21:15.391+0000] {subprocess.py:93} INFO -   File "/home/***/.local/lib/python3.8/site-packages/dbt/events/eventmgr.py", line 132, in __init__
[2023-09-20T11:21:15.392+0000] {subprocess.py:93} INFO -     super().__init__(event_manager, config)
[2023-09-20T11:21:15.392+0000] {subprocess.py:93} INFO -   File "/home/***/.local/lib/python3.8/site-packages/dbt/events/eventmgr.py", line 100, in __init__
[2023-09-20T11:21:15.392+0000] {subprocess.py:93} INFO -     file_handler = RotatingFileHandler(
[2023-09-20T11:21:15.392+0000] {subprocess.py:93} INFO -   File "/usr/local/lib/python3.8/logging/handlers.py", line 148, in __init__
[2023-09-20T11:21:15.392+0000] {subprocess.py:93} INFO -     BaseRotatingHandler.__init__(self, filename, mode, encoding, delay)
[2023-09-20T11:21:15.392+0000] {subprocess.py:93} INFO -   File "/usr/local/lib/python3.8/logging/handlers.py", line 55, in __init__
[2023-09-20T11:21:15.393+0000] {subprocess.py:93} INFO -     logging.FileHandler.__init__(self, filename, mode, encoding, delay)
[2023-09-20T11:21:15.393+0000] {subprocess.py:93} INFO -   File "/usr/local/lib/python3.8/logging/__init__.py", line 1147, in __init__
[2023-09-20T11:21:15.393+0000] {subprocess.py:93} INFO -     StreamHandler.__init__(self, self._open())
[2023-09-20T11:21:15.393+0000] {subprocess.py:93} INFO -   File "/usr/local/lib/python3.8/logging/__init__.py", line 1176, in _open
[2023-09-20T11:21:15.393+0000] {subprocess.py:93} INFO -     return open(self.baseFilename, self.mode, encoding=self.encoding)
[2023-09-20T11:21:15.393+0000] {subprocess.py:93} INFO - PermissionError: [Errno 13] Permission denied: '/app/logs/dbt.log'
[2023-09-20T11:21:15.394+0000] {subprocess.py:93} INFO - 
[2023-09-20T11:21:15.577+0000] {subprocess.py:97} INFO - Command exited with return code 2
[2023-09-20T11:21:15.590+0000] {taskinstance.py:1935} ERROR - Task failed with exception
Traceback (most recent call last):
  File "/home/airflow/.local/lib/python3.8/site-packages/airflow/operators/bash.py", line 210, in execute
    raise AirflowException(
airflow.exceptions.AirflowException: Bash command failed. The command returned a non-zero exit code 2.
[2023-09-20T11:21:15.594+0000] {taskinstance.py:1398} INFO - Marking task as FAILED. dag_id=main_dag, task_id=run_dbt, execution_date=20230920T112039, start_date=20230920T112109, end_date=20230920T112115
[2023-09-20T11:21:15.757+0000] {standard_task_runner.py:104} ERROR - Failed to execute job 6 for task run_dbt (Bash command failed. The command returned a non-zero exit code 2.; 85)
[2023-09-20T11:21:15.775+0000] {local_task_job_runner.py:228} INFO - Task exited with return code 1
[2023-09-20T11:21:15.801+0000] {taskinstance.py:2776} INFO - 0 downstream tasks scheduled from follow-on schedule check
