[2023-09-23T13:47:31.286+0000] {taskinstance.py:1157} INFO - Dependencies all met for dep_context=non-requeueable deps ti=<TaskInstance: tests_dag.test_imports manual__2023-09-23T13:47:28.860667+00:00 [queued]>
[2023-09-23T13:47:31.304+0000] {taskinstance.py:1157} INFO - Dependencies all met for dep_context=requeueable deps ti=<TaskInstance: tests_dag.test_imports manual__2023-09-23T13:47:28.860667+00:00 [queued]>
[2023-09-23T13:47:31.304+0000] {taskinstance.py:1359} INFO - Starting attempt 1 of 1
[2023-09-23T13:47:31.352+0000] {taskinstance.py:1380} INFO - Executing <Task(BashOperator): test_imports> on 2023-09-23 13:47:28.860667+00:00
[2023-09-23T13:47:31.358+0000] {standard_task_runner.py:57} INFO - Started process 510 to run task
[2023-09-23T13:47:31.368+0000] {standard_task_runner.py:84} INFO - Running: ['***', 'tasks', 'run', 'tests_dag', 'test_imports', 'manual__2023-09-23T13:47:28.860667+00:00', '--job-id', '14', '--raw', '--subdir', 'DAGS_FOLDER/test_dag.py', '--cfg-path', '/tmp/tmp9cpyjcgw']
[2023-09-23T13:47:31.371+0000] {standard_task_runner.py:85} INFO - Job 14: Subtask test_imports
[2023-09-23T13:47:31.488+0000] {task_command.py:415} INFO - Running <TaskInstance: tests_dag.test_imports manual__2023-09-23T13:47:28.860667+00:00 [running]> on host 4ef300bfa8d2
[2023-09-23T13:47:31.634+0000] {taskinstance.py:1660} INFO - Exporting env vars: AIRFLOW_CTX_DAG_OWNER='***' AIRFLOW_CTX_DAG_ID='tests_dag' AIRFLOW_CTX_TASK_ID='test_imports' AIRFLOW_CTX_EXECUTION_DATE='2023-09-23T13:47:28.860667+00:00' AIRFLOW_CTX_TRY_NUMBER='1' AIRFLOW_CTX_DAG_RUN_ID='manual__2023-09-23T13:47:28.860667+00:00'
[2023-09-23T13:47:31.636+0000] {subprocess.py:63} INFO - Tmp dir root location: /tmp
[2023-09-23T13:47:31.636+0000] {subprocess.py:75} INFO - Running command: ['/bin/bash', '-c', 'pytest /opt/***/dags/dag_scripts/tests/test_imports.py']
[2023-09-23T13:47:31.650+0000] {subprocess.py:86} INFO - Output:
[2023-09-23T13:47:32.376+0000] {subprocess.py:93} INFO - ============================= test session starts ==============================
[2023-09-23T13:47:32.377+0000] {subprocess.py:93} INFO - platform linux -- Python 3.8.18, pytest-7.4.2, pluggy-1.3.0
[2023-09-23T13:47:32.378+0000] {subprocess.py:93} INFO - rootdir: /opt/***/dags/dag_scripts/tests
[2023-09-23T13:47:32.379+0000] {subprocess.py:93} INFO - plugins: anyio-4.0.0
[2023-09-23T13:47:32.380+0000] {subprocess.py:93} INFO - collected 11 items
[2023-09-23T13:47:32.380+0000] {subprocess.py:93} INFO - 
[2023-09-23T13:47:34.349+0000] {subprocess.py:93} INFO - ../../opt/***/dags/dag_scripts/tests/test_imports.py FFFFF......     [100%]
[2023-09-23T13:47:34.350+0000] {subprocess.py:93} INFO - 
[2023-09-23T13:47:34.350+0000] {subprocess.py:93} INFO - =================================== FAILURES ===================================
[2023-09-23T13:47:34.351+0000] {subprocess.py:93} INFO - ___________________________ test_connections_import ____________________________
[2023-09-23T13:47:34.351+0000] {subprocess.py:93} INFO - 
[2023-09-23T13:47:34.351+0000] {subprocess.py:93} INFO -     def test_connections_import():
[2023-09-23T13:47:34.352+0000] {subprocess.py:93} INFO -         """Test the db connections import works"""
[2023-09-23T13:47:34.352+0000] {subprocess.py:93} INFO -         try:
[2023-09-23T13:47:34.352+0000] {subprocess.py:93} INFO - >           from dag_scripts.db_connections import db_connection_funcs
[2023-09-23T13:47:34.353+0000] {subprocess.py:93} INFO - E           ModuleNotFoundError: No module named 'dag_scripts'
[2023-09-23T13:47:34.353+0000] {subprocess.py:93} INFO - 
[2023-09-23T13:47:34.353+0000] {subprocess.py:93} INFO - /opt/***/dags/dag_scripts/tests/test_imports.py:11: ModuleNotFoundError
[2023-09-23T13:47:34.354+0000] {subprocess.py:93} INFO - 
[2023-09-23T13:47:34.354+0000] {subprocess.py:93} INFO - During handling of the above exception, another exception occurred:
[2023-09-23T13:47:34.354+0000] {subprocess.py:93} INFO - 
[2023-09-23T13:47:34.355+0000] {subprocess.py:93} INFO -     def test_connections_import():
[2023-09-23T13:47:34.355+0000] {subprocess.py:93} INFO -         """Test the db connections import works"""
[2023-09-23T13:47:34.355+0000] {subprocess.py:93} INFO -         try:
[2023-09-23T13:47:34.356+0000] {subprocess.py:93} INFO -             from dag_scripts.db_connections import db_connection_funcs
[2023-09-23T13:47:34.356+0000] {subprocess.py:93} INFO -         except ImportError:
[2023-09-23T13:47:34.358+0000] {subprocess.py:93} INFO - >           assert False
[2023-09-23T13:47:34.359+0000] {subprocess.py:93} INFO - E           assert False
[2023-09-23T13:47:34.360+0000] {subprocess.py:93} INFO - 
[2023-09-23T13:47:34.361+0000] {subprocess.py:93} INFO - /opt/***/dags/dag_scripts/tests/test_imports.py:13: AssertionError
[2023-09-23T13:47:34.362+0000] {subprocess.py:93} INFO - ___________________________ test_clear_mongo_import ____________________________
[2023-09-23T13:47:34.363+0000] {subprocess.py:93} INFO - 
[2023-09-23T13:47:34.363+0000] {subprocess.py:93} INFO -     def test_clear_mongo_import():
[2023-09-23T13:47:34.364+0000] {subprocess.py:93} INFO -         """Test the mongodb staging clearing import works"""
[2023-09-23T13:47:34.364+0000] {subprocess.py:93} INFO -         try:
[2023-09-23T13:47:34.364+0000] {subprocess.py:93} INFO - >           from dag_scripts import clear_mongodb_staging
[2023-09-23T13:47:34.365+0000] {subprocess.py:93} INFO - E           ModuleNotFoundError: No module named 'dag_scripts'
[2023-09-23T13:47:34.365+0000] {subprocess.py:93} INFO - 
[2023-09-23T13:47:34.366+0000] {subprocess.py:93} INFO - /opt/***/dags/dag_scripts/tests/test_imports.py:18: ModuleNotFoundError
[2023-09-23T13:47:34.366+0000] {subprocess.py:93} INFO - 
[2023-09-23T13:47:34.367+0000] {subprocess.py:93} INFO - During handling of the above exception, another exception occurred:
[2023-09-23T13:47:34.367+0000] {subprocess.py:93} INFO - 
[2023-09-23T13:47:34.367+0000] {subprocess.py:93} INFO -     def test_clear_mongo_import():
[2023-09-23T13:47:34.367+0000] {subprocess.py:93} INFO -         """Test the mongodb staging clearing import works"""
[2023-09-23T13:47:34.368+0000] {subprocess.py:93} INFO -         try:
[2023-09-23T13:47:34.368+0000] {subprocess.py:93} INFO -             from dag_scripts import clear_mongodb_staging
[2023-09-23T13:47:34.368+0000] {subprocess.py:93} INFO -         except ImportError:
[2023-09-23T13:47:34.368+0000] {subprocess.py:93} INFO - >           assert False
[2023-09-23T13:47:34.369+0000] {subprocess.py:93} INFO - E           assert False
[2023-09-23T13:47:34.369+0000] {subprocess.py:93} INFO - 
[2023-09-23T13:47:34.369+0000] {subprocess.py:93} INFO - /opt/***/dags/dag_scripts/tests/test_imports.py:20: AssertionError
[2023-09-23T13:47:34.370+0000] {subprocess.py:93} INFO - ___________________________ test_web_to_mongo_import ___________________________
[2023-09-23T13:47:34.370+0000] {subprocess.py:93} INFO - 
[2023-09-23T13:47:34.370+0000] {subprocess.py:93} INFO -     def test_web_to_mongo_import():
[2023-09-23T13:47:34.370+0000] {subprocess.py:93} INFO -         """Test the web to mongo import works"""
[2023-09-23T13:47:34.371+0000] {subprocess.py:93} INFO -         try:
[2023-09-23T13:47:34.371+0000] {subprocess.py:93} INFO - >           from dag_scripts import website_to_mongodb
[2023-09-23T13:47:34.371+0000] {subprocess.py:93} INFO - E           ModuleNotFoundError: No module named 'dag_scripts'
[2023-09-23T13:47:34.371+0000] {subprocess.py:93} INFO - 
[2023-09-23T13:47:34.372+0000] {subprocess.py:93} INFO - /opt/***/dags/dag_scripts/tests/test_imports.py:25: ModuleNotFoundError
[2023-09-23T13:47:34.372+0000] {subprocess.py:93} INFO - 
[2023-09-23T13:47:34.372+0000] {subprocess.py:93} INFO - During handling of the above exception, another exception occurred:
[2023-09-23T13:47:34.372+0000] {subprocess.py:93} INFO - 
[2023-09-23T13:47:34.373+0000] {subprocess.py:93} INFO -     def test_web_to_mongo_import():
[2023-09-23T13:47:34.373+0000] {subprocess.py:93} INFO -         """Test the web to mongo import works"""
[2023-09-23T13:47:34.374+0000] {subprocess.py:93} INFO -         try:
[2023-09-23T13:47:34.375+0000] {subprocess.py:93} INFO -             from dag_scripts import website_to_mongodb
[2023-09-23T13:47:34.376+0000] {subprocess.py:93} INFO -         except ImportError:
[2023-09-23T13:47:34.377+0000] {subprocess.py:93} INFO - >           assert False
[2023-09-23T13:47:34.378+0000] {subprocess.py:93} INFO - E           assert False
[2023-09-23T13:47:34.379+0000] {subprocess.py:93} INFO - 
[2023-09-23T13:47:34.379+0000] {subprocess.py:93} INFO - /opt/***/dags/dag_scripts/tests/test_imports.py:27: AssertionError
[2023-09-23T13:47:34.380+0000] {subprocess.py:93} INFO - ________________________ test_mongo_to_postgres_import _________________________
[2023-09-23T13:47:34.381+0000] {subprocess.py:93} INFO - 
[2023-09-23T13:47:34.382+0000] {subprocess.py:93} INFO -     def test_mongo_to_postgres_import():
[2023-09-23T13:47:34.382+0000] {subprocess.py:93} INFO -         """Test the web to mongo import works"""
[2023-09-23T13:47:34.382+0000] {subprocess.py:93} INFO -         try:
[2023-09-23T13:47:34.383+0000] {subprocess.py:93} INFO - >           from dag_scripts import mongodb_to_postgres
[2023-09-23T13:47:34.383+0000] {subprocess.py:93} INFO - E           ModuleNotFoundError: No module named 'dag_scripts'
[2023-09-23T13:47:34.384+0000] {subprocess.py:93} INFO - 
[2023-09-23T13:47:34.384+0000] {subprocess.py:93} INFO - /opt/***/dags/dag_scripts/tests/test_imports.py:32: ModuleNotFoundError
[2023-09-23T13:47:34.385+0000] {subprocess.py:93} INFO - 
[2023-09-23T13:47:34.385+0000] {subprocess.py:93} INFO - During handling of the above exception, another exception occurred:
[2023-09-23T13:47:34.385+0000] {subprocess.py:93} INFO - 
[2023-09-23T13:47:34.385+0000] {subprocess.py:93} INFO -     def test_mongo_to_postgres_import():
[2023-09-23T13:47:34.386+0000] {subprocess.py:93} INFO -         """Test the web to mongo import works"""
[2023-09-23T13:47:34.386+0000] {subprocess.py:93} INFO -         try:
[2023-09-23T13:47:34.386+0000] {subprocess.py:93} INFO -             from dag_scripts import mongodb_to_postgres
[2023-09-23T13:47:34.386+0000] {subprocess.py:93} INFO -         except ImportError:
[2023-09-23T13:47:34.387+0000] {subprocess.py:93} INFO - >           assert False
[2023-09-23T13:47:34.387+0000] {subprocess.py:93} INFO - E           assert False
[2023-09-23T13:47:34.387+0000] {subprocess.py:93} INFO - 
[2023-09-23T13:47:34.387+0000] {subprocess.py:93} INFO - /opt/***/dags/dag_scripts/tests/test_imports.py:34: AssertionError
[2023-09-23T13:47:34.388+0000] {subprocess.py:93} INFO - ________________________ test_postgres_to_redis_import _________________________
[2023-09-23T13:47:34.388+0000] {subprocess.py:93} INFO - 
[2023-09-23T13:47:34.389+0000] {subprocess.py:93} INFO -     def test_postgres_to_redis_import():
[2023-09-23T13:47:34.389+0000] {subprocess.py:93} INFO -         """Test the web to mongo import works"""
[2023-09-23T13:47:34.390+0000] {subprocess.py:93} INFO -         try:
[2023-09-23T13:47:34.391+0000] {subprocess.py:93} INFO - >           from dag_scripts import mongodb_to_postgres
[2023-09-23T13:47:34.392+0000] {subprocess.py:93} INFO - E           ModuleNotFoundError: No module named 'dag_scripts'
[2023-09-23T13:47:34.393+0000] {subprocess.py:93} INFO - 
[2023-09-23T13:47:34.394+0000] {subprocess.py:93} INFO - /opt/***/dags/dag_scripts/tests/test_imports.py:39: ModuleNotFoundError
[2023-09-23T13:47:34.395+0000] {subprocess.py:93} INFO - 
[2023-09-23T13:47:34.396+0000] {subprocess.py:93} INFO - During handling of the above exception, another exception occurred:
[2023-09-23T13:47:34.397+0000] {subprocess.py:93} INFO - 
[2023-09-23T13:47:34.397+0000] {subprocess.py:93} INFO -     def test_postgres_to_redis_import():
[2023-09-23T13:47:34.398+0000] {subprocess.py:93} INFO -         """Test the web to mongo import works"""
[2023-09-23T13:47:34.398+0000] {subprocess.py:93} INFO -         try:
[2023-09-23T13:47:34.398+0000] {subprocess.py:93} INFO -             from dag_scripts import mongodb_to_postgres
[2023-09-23T13:47:34.399+0000] {subprocess.py:93} INFO -         except ImportError:
[2023-09-23T13:47:34.399+0000] {subprocess.py:93} INFO - >           assert False
[2023-09-23T13:47:34.400+0000] {subprocess.py:93} INFO - E           assert False
[2023-09-23T13:47:34.400+0000] {subprocess.py:93} INFO - 
[2023-09-23T13:47:34.400+0000] {subprocess.py:93} INFO - /opt/***/dags/dag_scripts/tests/test_imports.py:41: AssertionError
[2023-09-23T13:47:34.401+0000] {subprocess.py:93} INFO - =========================== short test summary info ============================
[2023-09-23T13:47:34.401+0000] {subprocess.py:93} INFO - FAILED ../../opt/***/dags/dag_scripts/tests/test_imports.py::test_connections_import
[2023-09-23T13:47:34.401+0000] {subprocess.py:93} INFO - FAILED ../../opt/***/dags/dag_scripts/tests/test_imports.py::test_clear_mongo_import
[2023-09-23T13:47:34.402+0000] {subprocess.py:93} INFO - FAILED ../../opt/***/dags/dag_scripts/tests/test_imports.py::test_web_to_mongo_import
[2023-09-23T13:47:34.402+0000] {subprocess.py:93} INFO - FAILED ../../opt/***/dags/dag_scripts/tests/test_imports.py::test_mongo_to_postgres_import
[2023-09-23T13:47:34.402+0000] {subprocess.py:93} INFO - FAILED ../../opt/***/dags/dag_scripts/tests/test_imports.py::test_postgres_to_redis_import
[2023-09-23T13:47:34.403+0000] {subprocess.py:93} INFO - ========================= 5 failed, 6 passed in 2.02s ==========================
[2023-09-23T13:47:34.700+0000] {subprocess.py:97} INFO - Command exited with return code 1
[2023-09-23T13:47:34.718+0000] {taskinstance.py:1935} ERROR - Task failed with exception
Traceback (most recent call last):
  File "/home/airflow/.local/lib/python3.8/site-packages/airflow/operators/bash.py", line 210, in execute
    raise AirflowException(
airflow.exceptions.AirflowException: Bash command failed. The command returned a non-zero exit code 1.
[2023-09-23T13:47:34.724+0000] {taskinstance.py:1398} INFO - Marking task as FAILED. dag_id=tests_dag, task_id=test_imports, execution_date=20230923T134728, start_date=20230923T134731, end_date=20230923T134734
[2023-09-23T13:47:34.763+0000] {standard_task_runner.py:104} ERROR - Failed to execute job 14 for task test_imports (Bash command failed. The command returned a non-zero exit code 1.; 510)
[2023-09-23T13:47:34.808+0000] {local_task_job_runner.py:228} INFO - Task exited with return code 1
[2023-09-23T13:47:34.864+0000] {taskinstance.py:2776} INFO - 0 downstream tasks scheduled from follow-on schedule check
