[2023-09-21T09:01:41.796+0000] {taskinstance.py:1157} INFO - Dependencies all met for dep_context=non-requeueable deps ti=<TaskInstance: main_dag.run_dbt manual__2023-09-21T09:00:07.395410+00:00 [queued]>
[2023-09-21T09:01:41.814+0000] {taskinstance.py:1157} INFO - Dependencies all met for dep_context=requeueable deps ti=<TaskInstance: main_dag.run_dbt manual__2023-09-21T09:00:07.395410+00:00 [queued]>
[2023-09-21T09:01:41.814+0000] {taskinstance.py:1359} INFO - Starting attempt 1 of 1
[2023-09-21T09:01:41.846+0000] {taskinstance.py:1380} INFO - Executing <Task(BashOperator): run_dbt> on 2023-09-21 09:00:07.395410+00:00
[2023-09-21T09:01:41.853+0000] {standard_task_runner.py:57} INFO - Started process 927 to run task
[2023-09-21T09:01:41.860+0000] {standard_task_runner.py:84} INFO - Running: ['***', 'tasks', 'run', 'main_dag', 'run_dbt', 'manual__2023-09-21T09:00:07.395410+00:00', '--job-id', '37', '--raw', '--subdir', 'DAGS_FOLDER/main_dag.py', '--cfg-path', '/tmp/tmployltpjo']
[2023-09-21T09:01:41.863+0000] {standard_task_runner.py:85} INFO - Job 37: Subtask run_dbt
[2023-09-21T09:01:41.947+0000] {task_command.py:415} INFO - Running <TaskInstance: main_dag.run_dbt manual__2023-09-21T09:00:07.395410+00:00 [running]> on host efc7e3a30856
[2023-09-21T09:01:42.085+0000] {taskinstance.py:1660} INFO - Exporting env vars: AIRFLOW_CTX_DAG_OWNER='***' AIRFLOW_CTX_DAG_ID='main_dag' AIRFLOW_CTX_TASK_ID='run_dbt' AIRFLOW_CTX_EXECUTION_DATE='2023-09-21T09:00:07.395410+00:00' AIRFLOW_CTX_TRY_NUMBER='1' AIRFLOW_CTX_DAG_RUN_ID='manual__2023-09-21T09:00:07.395410+00:00'
[2023-09-21T09:01:42.089+0000] {subprocess.py:63} INFO - Tmp dir root location: /tmp
[2023-09-21T09:01:42.091+0000] {subprocess.py:75} INFO - Running command: ['/bin/bash', '-c', 'dbt run --profiles-dir /.dbt --project-dir /dbt_project']
[2023-09-21T09:01:42.111+0000] {subprocess.py:86} INFO - Output:
[2023-09-21T09:01:46.625+0000] {subprocess.py:93} INFO - [0m09:01:46  Running with dbt=1.5.3
[2023-09-21T09:01:46.862+0000] {subprocess.py:93} INFO - [0m09:01:46  Registered adapter: postgres=1.5.3
[2023-09-21T09:01:47.394+0000] {subprocess.py:93} INFO - [0m09:01:47  [[33mWARNING[0m]: Configuration paths exist in your dbt_project.yml file which do not apply to any resources.
[2023-09-21T09:01:47.394+0000] {subprocess.py:93} INFO - There are 1 unused configuration paths:
[2023-09-21T09:01:47.395+0000] {subprocess.py:93} INFO - - models.dbt_supermarket_data_engineering.example
[2023-09-21T09:01:47.441+0000] {subprocess.py:93} INFO - [0m09:01:47  Found 5 models, 0 tests, 1 snapshot, 0 analyses, 718 macros, 0 operations, 0 seed files, 1 source, 0 exposures, 0 metrics, 0 groups
[2023-09-21T09:01:47.446+0000] {subprocess.py:93} INFO - [0m09:01:47
[2023-09-21T09:01:47.739+0000] {subprocess.py:93} INFO - [0m09:01:47  Concurrency: 1 threads (target='dev')
[2023-09-21T09:01:47.744+0000] {subprocess.py:93} INFO - [0m09:01:47
[2023-09-21T09:01:47.761+0000] {subprocess.py:93} INFO - [0m09:01:47  1 of 5 START sql incremental model public.dim_product_descriptions ............. [RUN]
[2023-09-21T09:01:48.231+0000] {subprocess.py:93} INFO - [0m09:01:48  1 of 5 OK created sql incremental model public.dim_product_descriptions ........ [[32mINSERT 0 637[0m in 0.47s]
[2023-09-21T09:01:48.239+0000] {subprocess.py:93} INFO - [0m09:01:48  2 of 5 START sql incremental model public.fct_product_prices ................... [RUN]
[2023-09-21T09:01:48.382+0000] {subprocess.py:93} INFO - [0m09:01:48  2 of 5 ERROR creating sql incremental model public.fct_product_prices .......... [[31mERROR[0m in 0.14s]
[2023-09-21T09:01:48.385+0000] {subprocess.py:93} INFO - [0m09:01:48  3 of 5 START sql incremental model public.fct_product_specials ................. [RUN]
[2023-09-21T09:01:48.584+0000] {subprocess.py:93} INFO - [0m09:01:48  3 of 5 OK created sql incremental model public.fct_product_specials ............ [[32mINSERT 0 199[0m in 0.19s]
[2023-09-21T09:01:48.593+0000] {subprocess.py:93} INFO - [0m09:01:48  4 of 5 SKIP relation public.mart_pricing_over_time ............................. [[33mSKIP[0m]
[2023-09-21T09:01:48.597+0000] {subprocess.py:93} INFO - [0m09:01:48  5 of 5 START sql incremental model public.mart_specials_over_time .............. [RUN]
[2023-09-21T09:01:48.767+0000] {subprocess.py:93} INFO - [0m09:01:48  5 of 5 OK created sql incremental model public.mart_specials_over_time ......... [[32mINSERT 0 199[0m in 0.17s]
[2023-09-21T09:01:48.799+0000] {subprocess.py:93} INFO - [0m09:01:48
[2023-09-21T09:01:48.800+0000] {subprocess.py:93} INFO - [0m09:01:48  Finished running 5 incremental models in 0 hours 0 minutes and 1.35 seconds (1.35s).
[2023-09-21T09:01:48.894+0000] {subprocess.py:93} INFO - [0m09:01:48
[2023-09-21T09:01:48.895+0000] {subprocess.py:93} INFO - [0m09:01:48  [31mCompleted with 1 error and 0 warnings:[0m
[2023-09-21T09:01:48.896+0000] {subprocess.py:93} INFO - [0m09:01:48
[2023-09-21T09:01:48.897+0000] {subprocess.py:93} INFO - [0m09:01:48  [33mDatabase Error in model fct_product_prices (models/fct_product_prices.sql)[0m
[2023-09-21T09:01:48.898+0000] {subprocess.py:93} INFO - [0m09:01:48    invalid input syntax for type numeric: ""
[2023-09-21T09:01:48.899+0000] {subprocess.py:93} INFO - [0m09:01:48    compiled Code at target/run/dbt_supermarket_data_engineering/models/fct_product_prices.sql
[2023-09-21T09:01:48.899+0000] {subprocess.py:93} INFO - [0m09:01:48
[2023-09-21T09:01:48.900+0000] {subprocess.py:93} INFO - [0m09:01:48  Done. PASS=3 WARN=0 ERROR=1 SKIP=1 TOTAL=5
[2023-09-21T09:01:50.603+0000] {subprocess.py:97} INFO - Command exited with return code 1
[2023-09-21T09:01:50.621+0000] {taskinstance.py:1935} ERROR - Task failed with exception
Traceback (most recent call last):
  File "/home/airflow/.local/lib/python3.8/site-packages/airflow/operators/bash.py", line 210, in execute
    raise AirflowException(
airflow.exceptions.AirflowException: Bash command failed. The command returned a non-zero exit code 1.
[2023-09-21T09:01:50.627+0000] {taskinstance.py:1398} INFO - Marking task as FAILED. dag_id=main_dag, task_id=run_dbt, execution_date=20230921T090007, start_date=20230921T090141, end_date=20230921T090150
[2023-09-21T09:01:50.658+0000] {standard_task_runner.py:104} ERROR - Failed to execute job 37 for task run_dbt (Bash command failed. The command returned a non-zero exit code 1.; 927)
[2023-09-21T09:01:50.684+0000] {local_task_job_runner.py:228} INFO - Task exited with return code 1
[2023-09-21T09:01:50.737+0000] {taskinstance.py:2776} INFO - 0 downstream tasks scheduled from follow-on schedule check
