[2023-09-20T10:08:01.842+0000] {taskinstance.py:1157} INFO - Dependencies all met for dep_context=non-requeueable deps ti=<TaskInstance: main_dag.clear_mongodb manual__2023-09-20T10:07:43.385950+00:00 [queued]>
[2023-09-20T10:08:01.918+0000] {taskinstance.py:1157} INFO - Dependencies all met for dep_context=requeueable deps ti=<TaskInstance: main_dag.clear_mongodb manual__2023-09-20T10:07:43.385950+00:00 [queued]>
[2023-09-20T10:08:01.918+0000] {taskinstance.py:1359} INFO - Starting attempt 1 of 1
[2023-09-20T10:08:02.442+0000] {taskinstance.py:1380} INFO - Executing <Task(PythonOperator): clear_mongodb> on 2023-09-20 10:07:43.385950+00:00
[2023-09-20T10:08:02.452+0000] {standard_task_runner.py:57} INFO - Started process 253 to run task
[2023-09-20T10:08:02.456+0000] {standard_task_runner.py:84} INFO - Running: ['***', 'tasks', 'run', 'main_dag', 'clear_mongodb', 'manual__2023-09-20T10:07:43.385950+00:00', '--job-id', '13', '--raw', '--subdir', 'DAGS_FOLDER/main_dag.py', '--cfg-path', '/tmp/tmp0mxd3i31']
[2023-09-20T10:08:09.067+0000] {standard_task_runner.py:85} INFO - Job 13: Subtask clear_mongodb
[2023-09-20T10:08:09.166+0000] {task_command.py:415} INFO - Running <TaskInstance: main_dag.clear_mongodb manual__2023-09-20T10:07:43.385950+00:00 [running]> on host fb50cb700c4d
[2023-09-20T10:08:09.353+0000] {taskinstance.py:1660} INFO - Exporting env vars: AIRFLOW_CTX_DAG_OWNER='***' AIRFLOW_CTX_DAG_ID='main_dag' AIRFLOW_CTX_TASK_ID='clear_mongodb' AIRFLOW_CTX_EXECUTION_DATE='2023-09-20T10:07:43.385950+00:00' AIRFLOW_CTX_TRY_NUMBER='1' AIRFLOW_CTX_DAG_RUN_ID='manual__2023-09-20T10:07:43.385950+00:00'
[2023-09-20T10:08:10.556+0000] {taskinstance.py:1935} ERROR - Task failed with exception
Traceback (most recent call last):
  File "/home/airflow/.local/lib/python3.8/site-packages/airflow/operators/python.py", line 192, in execute
    return_value = self.execute_callable()
  File "/home/airflow/.local/lib/python3.8/site-packages/airflow/operators/python.py", line 209, in execute_callable
    return self.python_callable(*self.op_args, **self.op_kwargs)
  File "/opt/airflow/dags/dag_scripts/clear_mongodb_staging.py", line 13, in main
    mongodb_collection.delete_many({})
  File "/home/airflow/.local/lib/python3.8/site-packages/pymongo/collection.py", line 1426, in delete_many
    self._delete_retryable(
  File "/home/airflow/.local/lib/python3.8/site-packages/pymongo/collection.py", line 1301, in _delete_retryable
    return self.__database.client._retryable_write(
  File "/home/airflow/.local/lib/python3.8/site-packages/pymongo/mongo_client.py", line 1493, in _retryable_write
    return self._retry_with_session(retryable, func, s, None)
  File "/home/airflow/.local/lib/python3.8/site-packages/pymongo/mongo_client.py", line 1360, in _retry_with_session
    return self._retry_internal(retryable, func, session, bulk)
  File "/home/airflow/.local/lib/python3.8/site-packages/pymongo/_csot.py", line 106, in csot_wrapper
    return func(self, *args, **kwargs)
  File "/home/airflow/.local/lib/python3.8/site-packages/pymongo/mongo_client.py", line 1392, in _retry_internal
    with self._get_socket(server, session) as sock_info:
  File "/usr/local/lib/python3.8/contextlib.py", line 113, in __enter__
    return next(self.gen)
  File "/home/airflow/.local/lib/python3.8/site-packages/pymongo/mongo_client.py", line 1228, in _get_socket
    with server.get_socket(handler=err_handler) as sock_info:
  File "/usr/local/lib/python3.8/contextlib.py", line 113, in __enter__
    return next(self.gen)
  File "/home/airflow/.local/lib/python3.8/site-packages/pymongo/pool.py", line 1522, in get_socket
    sock_info = self._get_socket(handler=handler)
  File "/home/airflow/.local/lib/python3.8/site-packages/pymongo/pool.py", line 1635, in _get_socket
    sock_info = self.connect(handler=handler)
  File "/home/airflow/.local/lib/python3.8/site-packages/pymongo/pool.py", line 1493, in connect
    sock_info.authenticate()
  File "/home/airflow/.local/lib/python3.8/site-packages/pymongo/pool.py", line 987, in authenticate
    auth.authenticate(creds, self, reauthenticate=reauthenticate)
  File "/home/airflow/.local/lib/python3.8/site-packages/pymongo/auth.py", line 617, in authenticate
    auth_func(credentials, sock_info)
  File "/home/airflow/.local/lib/python3.8/site-packages/pymongo/auth.py", line 522, in _authenticate_default
    return _authenticate_scram(credentials, sock_info, "SCRAM-SHA-1")
  File "/home/airflow/.local/lib/python3.8/site-packages/pymongo/auth.py", line 248, in _authenticate_scram
    res = sock_info.command(source, cmd)
  File "/home/airflow/.local/lib/python3.8/site-packages/pymongo/helpers.py", line 279, in inner
    return func(*args, **kwargs)
  File "/home/airflow/.local/lib/python3.8/site-packages/pymongo/pool.py", line 879, in command
    return command(
  File "/home/airflow/.local/lib/python3.8/site-packages/pymongo/network.py", line 166, in command
    helpers._check_command_response(
  File "/home/airflow/.local/lib/python3.8/site-packages/pymongo/helpers.py", line 194, in _check_command_response
    raise OperationFailure(errmsg, code, response, max_wire_version)
pymongo.errors.OperationFailure: Authentication failed., full error: {'ok': 0.0, 'errmsg': 'Authentication failed.', 'code': 18, 'codeName': 'AuthenticationFailed'}
[2023-09-20T10:08:10.621+0000] {taskinstance.py:1398} INFO - Marking task as FAILED. dag_id=main_dag, task_id=clear_mongodb, execution_date=20230920T100743, start_date=20230920T100801, end_date=20230920T100810
[2023-09-20T10:08:10.695+0000] {standard_task_runner.py:104} ERROR - Failed to execute job 13 for task clear_mongodb (Authentication failed., full error: {'ok': 0.0, 'errmsg': 'Authentication failed.', 'code': 18, 'codeName': 'AuthenticationFailed'}; 253)
[2023-09-20T10:08:10.714+0000] {local_task_job_runner.py:228} INFO - Task exited with return code 1
[2023-09-20T10:08:10.751+0000] {taskinstance.py:2776} INFO - 0 downstream tasks scheduled from follow-on schedule check
