[2023-09-23T13:27:39.777+0000] {taskinstance.py:1157} INFO - Dependencies all met for dep_context=non-requeueable deps ti=<TaskInstance: tests_dag.test_imports manual__2023-09-23T13:27:36.237519+00:00 [queued]>
[2023-09-23T13:27:39.801+0000] {taskinstance.py:1157} INFO - Dependencies all met for dep_context=requeueable deps ti=<TaskInstance: tests_dag.test_imports manual__2023-09-23T13:27:36.237519+00:00 [queued]>
[2023-09-23T13:27:39.802+0000] {taskinstance.py:1359} INFO - Starting attempt 1 of 1
[2023-09-23T13:27:39.842+0000] {taskinstance.py:1380} INFO - Executing <Task(BashOperator): test_imports> on 2023-09-23 13:27:36.237519+00:00
[2023-09-23T13:27:39.851+0000] {standard_task_runner.py:57} INFO - Started process 128 to run task
[2023-09-23T13:27:39.860+0000] {standard_task_runner.py:84} INFO - Running: ['***', 'tasks', 'run', 'tests_dag', 'test_imports', 'manual__2023-09-23T13:27:36.237519+00:00', '--job-id', '4', '--raw', '--subdir', 'DAGS_FOLDER/test_dag.py', '--cfg-path', '/tmp/tmph7bfbtdq']
[2023-09-23T13:27:39.867+0000] {standard_task_runner.py:85} INFO - Job 4: Subtask test_imports
[2023-09-23T13:27:39.959+0000] {task_command.py:415} INFO - Running <TaskInstance: tests_dag.test_imports manual__2023-09-23T13:27:36.237519+00:00 [running]> on host 4ef300bfa8d2
[2023-09-23T13:27:40.144+0000] {taskinstance.py:1660} INFO - Exporting env vars: AIRFLOW_CTX_DAG_OWNER='***' AIRFLOW_CTX_DAG_ID='tests_dag' AIRFLOW_CTX_TASK_ID='test_imports' AIRFLOW_CTX_EXECUTION_DATE='2023-09-23T13:27:36.237519+00:00' AIRFLOW_CTX_TRY_NUMBER='1' AIRFLOW_CTX_DAG_RUN_ID='manual__2023-09-23T13:27:36.237519+00:00'
[2023-09-23T13:27:40.146+0000] {subprocess.py:63} INFO - Tmp dir root location: /tmp
[2023-09-23T13:27:40.148+0000] {subprocess.py:75} INFO - Running command: ['/bin/bash', '-c', 'pytest /opt/***/dags/dag_scripts/tests/test_imports.py > /opt/***/dags/dag_scripts/tests/test_imports.log']
[2023-09-23T13:27:40.164+0000] {subprocess.py:86} INFO - Output:
[2023-09-23T13:27:49.338+0000] {subprocess.py:97} INFO - Command exited with return code 1
[2023-09-23T13:27:49.350+0000] {taskinstance.py:1935} ERROR - Task failed with exception
Traceback (most recent call last):
  File "/home/airflow/.local/lib/python3.8/site-packages/airflow/operators/bash.py", line 210, in execute
    raise AirflowException(
airflow.exceptions.AirflowException: Bash command failed. The command returned a non-zero exit code 1.
[2023-09-23T13:27:49.355+0000] {taskinstance.py:1398} INFO - Marking task as FAILED. dag_id=tests_dag, task_id=test_imports, execution_date=20230923T132736, start_date=20230923T132739, end_date=20230923T132749
[2023-09-23T13:27:49.383+0000] {standard_task_runner.py:104} ERROR - Failed to execute job 4 for task test_imports (Bash command failed. The command returned a non-zero exit code 1.; 128)
[2023-09-23T13:27:49.409+0000] {local_task_job_runner.py:228} INFO - Task exited with return code 1
[2023-09-23T13:27:49.443+0000] {taskinstance.py:2776} INFO - 0 downstream tasks scheduled from follow-on schedule check
