[2023-09-20T10:23:21.405+0000] {taskinstance.py:1157} INFO - Dependencies all met for dep_context=non-requeueable deps ti=<TaskInstance: main_dag.clear_mongodb manual__2023-09-20T10:23:17.170205+00:00 [queued]>
[2023-09-20T10:23:21.416+0000] {taskinstance.py:1157} INFO - Dependencies all met for dep_context=requeueable deps ti=<TaskInstance: main_dag.clear_mongodb manual__2023-09-20T10:23:17.170205+00:00 [queued]>
[2023-09-20T10:23:21.416+0000] {taskinstance.py:1359} INFO - Starting attempt 1 of 1
[2023-09-20T10:23:21.443+0000] {taskinstance.py:1380} INFO - Executing <Task(PythonOperator): clear_mongodb> on 2023-09-20 10:23:17.170205+00:00
[2023-09-20T10:23:21.447+0000] {standard_task_runner.py:57} INFO - Started process 74 to run task
[2023-09-20T10:23:21.451+0000] {standard_task_runner.py:84} INFO - Running: ['***', 'tasks', 'run', 'main_dag', 'clear_mongodb', 'manual__2023-09-20T10:23:17.170205+00:00', '--job-id', '3', '--raw', '--subdir', 'DAGS_FOLDER/main_dag.py', '--cfg-path', '/tmp/tmputbruzju']
[2023-09-20T10:23:21.454+0000] {standard_task_runner.py:85} INFO - Job 3: Subtask clear_mongodb
[2023-09-20T10:23:21.521+0000] {task_command.py:415} INFO - Running <TaskInstance: main_dag.clear_mongodb manual__2023-09-20T10:23:17.170205+00:00 [running]> on host 5b55dfd0f51a
[2023-09-20T10:23:21.654+0000] {taskinstance.py:1660} INFO - Exporting env vars: AIRFLOW_CTX_DAG_OWNER='***' AIRFLOW_CTX_DAG_ID='main_dag' AIRFLOW_CTX_TASK_ID='clear_mongodb' AIRFLOW_CTX_EXECUTION_DATE='2023-09-20T10:23:17.170205+00:00' AIRFLOW_CTX_TRY_NUMBER='1' AIRFLOW_CTX_DAG_RUN_ID='manual__2023-09-20T10:23:17.170205+00:00'
[2023-09-20T10:23:51.826+0000] {taskinstance.py:1935} ERROR - Task failed with exception
Traceback (most recent call last):
  File "/home/airflow/.local/lib/python3.8/site-packages/airflow/operators/python.py", line 192, in execute
    return_value = self.execute_callable()
  File "/home/airflow/.local/lib/python3.8/site-packages/airflow/operators/python.py", line 209, in execute_callable
    return self.python_callable(*self.op_args, **self.op_kwargs)
  File "/opt/airflow/dags/dag_scripts/clear_mongodb_staging.py", line 13, in main
    mongodb_collection.delete_many({})
  File "/home/airflow/.local/lib/python3.8/site-packages/pymongo/collection.py", line 1426, in delete_many
    self._delete_retryable(
  File "/home/airflow/.local/lib/python3.8/site-packages/pymongo/collection.py", line 1301, in _delete_retryable
    return self.__database.client._retryable_write(
  File "/home/airflow/.local/lib/python3.8/site-packages/pymongo/mongo_client.py", line 1492, in _retryable_write
    with self._tmp_session(session) as s:
  File "/usr/local/lib/python3.8/contextlib.py", line 113, in __enter__
    return next(self.gen)
  File "/home/airflow/.local/lib/python3.8/site-packages/pymongo/mongo_client.py", line 1775, in _tmp_session
    s = self._ensure_session(session)
  File "/home/airflow/.local/lib/python3.8/site-packages/pymongo/mongo_client.py", line 1758, in _ensure_session
    return self.__start_session(True, causal_consistency=False)
  File "/home/airflow/.local/lib/python3.8/site-packages/pymongo/mongo_client.py", line 1703, in __start_session
    self._topology._check_implicit_session_support()
  File "/home/airflow/.local/lib/python3.8/site-packages/pymongo/topology.py", line 538, in _check_implicit_session_support
    self._check_session_support()
  File "/home/airflow/.local/lib/python3.8/site-packages/pymongo/topology.py", line 554, in _check_session_support
    self._select_servers_loop(
  File "/home/airflow/.local/lib/python3.8/site-packages/pymongo/topology.py", line 238, in _select_servers_loop
    raise ServerSelectionTimeoutError(
pymongo.errors.ServerSelectionTimeoutError: mongodb:27018: [Errno 111] Connection refused, Timeout: 30s, Topology Description: <TopologyDescription id: 650ac81963393408e35477ae, topology_type: Unknown, servers: [<ServerDescription ('mongodb', 27018) server_type: Unknown, rtt: None, error=AutoReconnect('mongodb:27018: [Errno 111] Connection refused')>]>
[2023-09-20T10:23:51.847+0000] {taskinstance.py:1398} INFO - Marking task as FAILED. dag_id=main_dag, task_id=clear_mongodb, execution_date=20230920T102317, start_date=20230920T102321, end_date=20230920T102351
[2023-09-20T10:23:51.894+0000] {standard_task_runner.py:104} ERROR - Failed to execute job 3 for task clear_mongodb (mongodb:27018: [Errno 111] Connection refused, Timeout: 30s, Topology Description: <TopologyDescription id: 650ac81963393408e35477ae, topology_type: Unknown, servers: [<ServerDescription ('mongodb', 27018) server_type: Unknown, rtt: None, error=AutoReconnect('mongodb:27018: [Errno 111] Connection refused')>]>; 74)
[2023-09-20T10:23:51.912+0000] {local_task_job_runner.py:228} INFO - Task exited with return code 1
[2023-09-20T10:23:51.971+0000] {taskinstance.py:2776} INFO - 0 downstream tasks scheduled from follow-on schedule check
