[2023-09-23T13:54:11.108+0000] {taskinstance.py:1157} INFO - Dependencies all met for dep_context=non-requeueable deps ti=<TaskInstance: tests_dag.test_db_conns manual__2023-09-23T13:54:02.913446+00:00 [queued]>
[2023-09-23T13:54:11.126+0000] {taskinstance.py:1157} INFO - Dependencies all met for dep_context=requeueable deps ti=<TaskInstance: tests_dag.test_db_conns manual__2023-09-23T13:54:02.913446+00:00 [queued]>
[2023-09-23T13:54:11.126+0000] {taskinstance.py:1359} INFO - Starting attempt 1 of 1
[2023-09-23T13:54:11.161+0000] {taskinstance.py:1380} INFO - Executing <Task(BashOperator): test_db_conns> on 2023-09-23 13:54:02.913446+00:00
[2023-09-23T13:54:11.169+0000] {standard_task_runner.py:57} INFO - Started process 641 to run task
[2023-09-23T13:54:11.173+0000] {standard_task_runner.py:84} INFO - Running: ['***', 'tasks', 'run', 'tests_dag', 'test_db_conns', 'manual__2023-09-23T13:54:02.913446+00:00', '--job-id', '18', '--raw', '--subdir', 'DAGS_FOLDER/test_dag.py', '--cfg-path', '/tmp/tmpge6_a8d5']
[2023-09-23T13:54:11.176+0000] {standard_task_runner.py:85} INFO - Job 18: Subtask test_db_conns
[2023-09-23T13:54:11.247+0000] {task_command.py:415} INFO - Running <TaskInstance: tests_dag.test_db_conns manual__2023-09-23T13:54:02.913446+00:00 [running]> on host 4ef300bfa8d2
[2023-09-23T13:54:11.387+0000] {taskinstance.py:1660} INFO - Exporting env vars: AIRFLOW_CTX_DAG_OWNER='***' AIRFLOW_CTX_DAG_ID='tests_dag' AIRFLOW_CTX_TASK_ID='test_db_conns' AIRFLOW_CTX_EXECUTION_DATE='2023-09-23T13:54:02.913446+00:00' AIRFLOW_CTX_TRY_NUMBER='1' AIRFLOW_CTX_DAG_RUN_ID='manual__2023-09-23T13:54:02.913446+00:00'
[2023-09-23T13:54:11.389+0000] {subprocess.py:63} INFO - Tmp dir root location: /tmp
[2023-09-23T13:54:11.389+0000] {subprocess.py:75} INFO - Running command: ['/bin/bash', '-c', 'pytest /opt/***/dags/dag_scripts/tests/test_db_connections.py']
[2023-09-23T13:54:11.403+0000] {subprocess.py:86} INFO - Output:
[2023-09-23T13:54:12.591+0000] {subprocess.py:93} INFO - ============================= test session starts ==============================
[2023-09-23T13:54:12.592+0000] {subprocess.py:93} INFO - platform linux -- Python 3.8.18, pytest-7.4.2, pluggy-1.3.0
[2023-09-23T13:54:12.592+0000] {subprocess.py:93} INFO - rootdir: /opt/***/dags/dag_scripts/tests
[2023-09-23T13:54:12.593+0000] {subprocess.py:93} INFO - plugins: anyio-4.0.0
[2023-09-23T13:54:12.593+0000] {subprocess.py:93} INFO - collected 7 items
[2023-09-23T13:54:12.593+0000] {subprocess.py:93} INFO - 
[2023-09-23T13:54:13.388+0000] {subprocess.py:93} INFO - ../../opt/***/dags/dag_scripts/tests/test_db_connections.py .....F.  [100%]
[2023-09-23T13:54:13.389+0000] {subprocess.py:93} INFO - 
[2023-09-23T13:54:13.390+0000] {subprocess.py:93} INFO - =================================== FAILURES ===================================
[2023-09-23T13:54:13.390+0000] {subprocess.py:93} INFO - ___________________________ test_postgres_connection ___________________________
[2023-09-23T13:54:13.390+0000] {subprocess.py:93} INFO - 
[2023-09-23T13:54:13.390+0000] {subprocess.py:93} INFO -     def test_postgres_connection():
[2023-09-23T13:54:13.391+0000] {subprocess.py:93} INFO -         """Test that the user can connect to the PostgreSQL database"""
[2023-09-23T13:54:13.391+0000] {subprocess.py:93} INFO -         postgresql_conn = db_connection_funcs.create_postgresql_engine()
[2023-09-23T13:54:13.391+0000] {subprocess.py:93} INFO - >       assert postgresql_conn.connect().is_valid
[2023-09-23T13:54:13.391+0000] {subprocess.py:93} INFO - E       AttributeError: 'Connection' object has no attribute 'is_valid'
[2023-09-23T13:54:13.391+0000] {subprocess.py:93} INFO - 
[2023-09-23T13:54:13.391+0000] {subprocess.py:93} INFO - /opt/***/dags/dag_scripts/tests/test_db_connections.py:57: AttributeError
[2023-09-23T13:54:13.392+0000] {subprocess.py:93} INFO - =============================== warnings summary ===============================
[2023-09-23T13:54:13.392+0000] {subprocess.py:93} INFO - ../../opt/***/dags/dag_scripts/tests/test_db_connections.py:64
[2023-09-23T13:54:13.392+0000] {subprocess.py:93} INFO -   /opt/***/dags/dag_scripts/tests/test_db_connections.py:64: PytestAssertRewriteWarning: assertion is always true, perhaps remove parentheses?
[2023-09-23T13:54:13.392+0000] {subprocess.py:93} INFO -     assert (response,True)
[2023-09-23T13:54:13.393+0000] {subprocess.py:93} INFO - 
[2023-09-23T13:54:13.393+0000] {subprocess.py:93} INFO - -- Docs: https://docs.pytest.org/en/stable/how-to/capture-warnings.html
[2023-09-23T13:54:13.393+0000] {subprocess.py:93} INFO - =========================== short test summary info ============================
[2023-09-23T13:54:13.393+0000] {subprocess.py:93} INFO - FAILED ../../opt/***/dags/dag_scripts/tests/test_db_connections.py::test_postgres_connection
[2023-09-23T13:54:13.393+0000] {subprocess.py:93} INFO - ==================== 1 failed, 6 passed, 1 warning in 1.35s ====================
[2023-09-23T13:54:13.868+0000] {subprocess.py:97} INFO - Command exited with return code 1
[2023-09-23T13:54:13.891+0000] {taskinstance.py:1935} ERROR - Task failed with exception
Traceback (most recent call last):
  File "/home/airflow/.local/lib/python3.8/site-packages/airflow/operators/bash.py", line 210, in execute
    raise AirflowException(
airflow.exceptions.AirflowException: Bash command failed. The command returned a non-zero exit code 1.
[2023-09-23T13:54:13.898+0000] {taskinstance.py:1398} INFO - Marking task as FAILED. dag_id=tests_dag, task_id=test_db_conns, execution_date=20230923T135402, start_date=20230923T135411, end_date=20230923T135413
[2023-09-23T13:54:14.240+0000] {standard_task_runner.py:104} ERROR - Failed to execute job 18 for task test_db_conns (Bash command failed. The command returned a non-zero exit code 1.; 641)
[2023-09-23T13:54:14.282+0000] {local_task_job_runner.py:228} INFO - Task exited with return code 1
[2023-09-23T13:54:14.338+0000] {taskinstance.py:2776} INFO - 0 downstream tasks scheduled from follow-on schedule check
