[2023-09-21T06:16:39.972+0000] {taskinstance.py:1157} INFO - Dependencies all met for dep_context=non-requeueable deps ti=<TaskInstance: main_dag.install_dbt_deps manual__2023-09-21T06:16:07.579525+00:00 [queued]>
[2023-09-21T06:16:39.988+0000] {taskinstance.py:1157} INFO - Dependencies all met for dep_context=requeueable deps ti=<TaskInstance: main_dag.install_dbt_deps manual__2023-09-21T06:16:07.579525+00:00 [queued]>
[2023-09-21T06:16:39.989+0000] {taskinstance.py:1359} INFO - Starting attempt 1 of 1
[2023-09-21T06:16:40.257+0000] {taskinstance.py:1380} INFO - Executing <Task(BashOperator): install_dbt_deps> on 2023-09-21 06:16:07.579525+00:00
[2023-09-21T06:16:40.264+0000] {standard_task_runner.py:57} INFO - Started process 91 to run task
[2023-09-21T06:16:40.272+0000] {standard_task_runner.py:84} INFO - Running: ['***', 'tasks', 'run', 'main_dag', 'install_dbt_deps', 'manual__2023-09-21T06:16:07.579525+00:00', '--job-id', '18', '--raw', '--subdir', 'DAGS_FOLDER/main_dag.py', '--cfg-path', '/tmp/tmprpgguwvr']
[2023-09-21T06:16:40.276+0000] {standard_task_runner.py:85} INFO - Job 18: Subtask install_dbt_deps
[2023-09-21T06:16:40.391+0000] {task_command.py:415} INFO - Running <TaskInstance: main_dag.install_dbt_deps manual__2023-09-21T06:16:07.579525+00:00 [running]> on host 792a3b20ba0b
[2023-09-21T06:16:40.777+0000] {taskinstance.py:1660} INFO - Exporting env vars: AIRFLOW_CTX_DAG_OWNER='***' AIRFLOW_CTX_DAG_ID='main_dag' AIRFLOW_CTX_TASK_ID='install_dbt_deps' AIRFLOW_CTX_EXECUTION_DATE='2023-09-21T06:16:07.579525+00:00' AIRFLOW_CTX_TRY_NUMBER='1' AIRFLOW_CTX_DAG_RUN_ID='manual__2023-09-21T06:16:07.579525+00:00'
[2023-09-21T06:16:40.780+0000] {subprocess.py:63} INFO - Tmp dir root location: /tmp
[2023-09-21T06:16:40.945+0000] {subprocess.py:75} INFO - Running command: ['/bin/bash', '-c', 'dbt deps --profiles-dir /.dbt --project-dir /dbt_project']
[2023-09-21T06:16:40.989+0000] {subprocess.py:86} INFO - Output:
[2023-09-21T06:16:47.339+0000] {subprocess.py:93} INFO - [0m06:16:47  Encountered an error:
[2023-09-21T06:16:47.339+0000] {subprocess.py:93} INFO - [Errno 13] Permission denied: '/dbt_project/logs/dbt.log'
[2023-09-21T06:16:47.350+0000] {subprocess.py:93} INFO - [0m06:16:47  Traceback (most recent call last):
[2023-09-21T06:16:47.350+0000] {subprocess.py:93} INFO -   File "/home/***/.local/lib/python3.8/site-packages/dbt/cli/requires.py", line 86, in wrapper
[2023-09-21T06:16:47.351+0000] {subprocess.py:93} INFO -     result, success = func(*args, **kwargs)
[2023-09-21T06:16:47.351+0000] {subprocess.py:93} INFO -   File "/home/***/.local/lib/python3.8/site-packages/dbt/cli/requires.py", line 47, in wrapper
[2023-09-21T06:16:47.352+0000] {subprocess.py:93} INFO -     setup_event_logger(flags=flags, callbacks=callbacks)
[2023-09-21T06:16:47.352+0000] {subprocess.py:93} INFO -   File "/home/***/.local/lib/python3.8/site-packages/dbt/events/functions.py", line 64, in setup_event_logger
[2023-09-21T06:16:47.352+0000] {subprocess.py:93} INFO -     EVENT_MANAGER.add_logger(
[2023-09-21T06:16:47.357+0000] {subprocess.py:93} INFO -   File "/home/***/.local/lib/python3.8/site-packages/dbt/events/eventmgr.py", line 211, in add_logger
[2023-09-21T06:16:47.357+0000] {subprocess.py:93} INFO -     else _TextLogger(self, config)
[2023-09-21T06:16:47.357+0000] {subprocess.py:93} INFO -   File "/home/***/.local/lib/python3.8/site-packages/dbt/events/eventmgr.py", line 132, in __init__
[2023-09-21T06:16:47.358+0000] {subprocess.py:93} INFO -     super().__init__(event_manager, config)
[2023-09-21T06:16:47.358+0000] {subprocess.py:93} INFO -   File "/home/***/.local/lib/python3.8/site-packages/dbt/events/eventmgr.py", line 100, in __init__
[2023-09-21T06:16:47.359+0000] {subprocess.py:93} INFO -     file_handler = RotatingFileHandler(
[2023-09-21T06:16:47.359+0000] {subprocess.py:93} INFO -   File "/usr/local/lib/python3.8/logging/handlers.py", line 148, in __init__
[2023-09-21T06:16:47.359+0000] {subprocess.py:93} INFO -     BaseRotatingHandler.__init__(self, filename, mode, encoding, delay)
[2023-09-21T06:16:47.359+0000] {subprocess.py:93} INFO -   File "/usr/local/lib/python3.8/logging/handlers.py", line 55, in __init__
[2023-09-21T06:16:47.360+0000] {subprocess.py:93} INFO -     logging.FileHandler.__init__(self, filename, mode, encoding, delay)
[2023-09-21T06:16:47.360+0000] {subprocess.py:93} INFO -   File "/usr/local/lib/python3.8/logging/__init__.py", line 1147, in __init__
[2023-09-21T06:16:47.361+0000] {subprocess.py:93} INFO -     StreamHandler.__init__(self, self._open())
[2023-09-21T06:16:47.361+0000] {subprocess.py:93} INFO -   File "/usr/local/lib/python3.8/logging/__init__.py", line 1176, in _open
[2023-09-21T06:16:47.361+0000] {subprocess.py:93} INFO -     return open(self.baseFilename, self.mode, encoding=self.encoding)
[2023-09-21T06:16:47.363+0000] {subprocess.py:93} INFO - PermissionError: [Errno 13] Permission denied: '/dbt_project/logs/dbt.log'
[2023-09-21T06:16:47.365+0000] {subprocess.py:93} INFO - 
[2023-09-21T06:16:47.577+0000] {subprocess.py:97} INFO - Command exited with return code 2
[2023-09-21T06:16:47.591+0000] {taskinstance.py:1935} ERROR - Task failed with exception
Traceback (most recent call last):
  File "/home/airflow/.local/lib/python3.8/site-packages/airflow/operators/bash.py", line 210, in execute
    raise AirflowException(
airflow.exceptions.AirflowException: Bash command failed. The command returned a non-zero exit code 2.
[2023-09-21T06:16:47.601+0000] {taskinstance.py:1398} INFO - Marking task as FAILED. dag_id=main_dag, task_id=install_dbt_deps, execution_date=20230921T061607, start_date=20230921T061639, end_date=20230921T061647
[2023-09-21T06:16:47.664+0000] {standard_task_runner.py:104} ERROR - Failed to execute job 18 for task install_dbt_deps (Bash command failed. The command returned a non-zero exit code 2.; 91)
[2023-09-21T06:16:47.699+0000] {local_task_job_runner.py:228} INFO - Task exited with return code 1
[2023-09-21T06:16:47.734+0000] {taskinstance.py:2776} INFO - 0 downstream tasks scheduled from follow-on schedule check
