[2023-09-21T09:31:20.824+0000] {taskinstance.py:1157} INFO - Dependencies all met for dep_context=non-requeueable deps ti=<TaskInstance: main_dag.run_dbt manual__2023-09-21T09:29:49.574429+00:00 [queued]>
[2023-09-21T09:31:20.840+0000] {taskinstance.py:1157} INFO - Dependencies all met for dep_context=requeueable deps ti=<TaskInstance: main_dag.run_dbt manual__2023-09-21T09:29:49.574429+00:00 [queued]>
[2023-09-21T09:31:20.841+0000] {taskinstance.py:1359} INFO - Starting attempt 1 of 1
[2023-09-21T09:31:20.865+0000] {taskinstance.py:1380} INFO - Executing <Task(BashOperator): run_dbt> on 2023-09-21 09:29:49.574429+00:00
[2023-09-21T09:31:20.876+0000] {standard_task_runner.py:57} INFO - Started process 222 to run task
[2023-09-21T09:31:20.880+0000] {standard_task_runner.py:84} INFO - Running: ['***', 'tasks', 'run', 'main_dag', 'run_dbt', 'manual__2023-09-21T09:29:49.574429+00:00', '--job-id', '56', '--raw', '--subdir', 'DAGS_FOLDER/main_dag.py', '--cfg-path', '/tmp/tmp4y_sh6qm']
[2023-09-21T09:31:20.885+0000] {standard_task_runner.py:85} INFO - Job 56: Subtask run_dbt
[2023-09-21T09:31:20.978+0000] {task_command.py:415} INFO - Running <TaskInstance: main_dag.run_dbt manual__2023-09-21T09:29:49.574429+00:00 [running]> on host 657a599f4719
[2023-09-21T09:31:21.184+0000] {taskinstance.py:1660} INFO - Exporting env vars: AIRFLOW_CTX_DAG_OWNER='***' AIRFLOW_CTX_DAG_ID='main_dag' AIRFLOW_CTX_TASK_ID='run_dbt' AIRFLOW_CTX_EXECUTION_DATE='2023-09-21T09:29:49.574429+00:00' AIRFLOW_CTX_TRY_NUMBER='1' AIRFLOW_CTX_DAG_RUN_ID='manual__2023-09-21T09:29:49.574429+00:00'
[2023-09-21T09:31:21.190+0000] {subprocess.py:63} INFO - Tmp dir root location: /tmp
[2023-09-21T09:31:21.191+0000] {subprocess.py:75} INFO - Running command: ['/bin/bash', '-c', 'dbt run --profiles-dir /.dbt --project-dir /dbt_project']
[2023-09-21T09:31:21.213+0000] {subprocess.py:86} INFO - Output:
[2023-09-21T09:31:25.563+0000] {subprocess.py:93} INFO - [0m09:31:25  Running with dbt=1.5.3
[2023-09-21T09:31:25.837+0000] {subprocess.py:93} INFO - [0m09:31:25  Registered adapter: postgres=1.5.3
[2023-09-21T09:31:27.061+0000] {subprocess.py:93} INFO - [0m09:31:27  [[33mWARNING[0m]: Configuration paths exist in your dbt_project.yml file which do not apply to any resources.
[2023-09-21T09:31:27.062+0000] {subprocess.py:93} INFO - There are 1 unused configuration paths:
[2023-09-21T09:31:27.063+0000] {subprocess.py:93} INFO - - models.dbt_supermarket_data_engineering.example
[2023-09-21T09:31:27.525+0000] {subprocess.py:93} INFO - [0m09:31:27  Found 5 models, 0 tests, 1 snapshot, 0 analyses, 718 macros, 0 operations, 0 seed files, 1 source, 0 exposures, 0 metrics, 0 groups
[2023-09-21T09:31:27.529+0000] {subprocess.py:93} INFO - [0m09:31:27
[2023-09-21T09:31:27.898+0000] {subprocess.py:93} INFO - [0m09:31:27  Concurrency: 1 threads (target='dev')
[2023-09-21T09:31:27.901+0000] {subprocess.py:93} INFO - [0m09:31:27
[2023-09-21T09:31:27.916+0000] {subprocess.py:93} INFO - [0m09:31:27  1 of 5 START sql incremental model public.dim_product_descriptions ............. [RUN]
[2023-09-21T09:31:28.311+0000] {subprocess.py:93} INFO - [0m09:31:28  1 of 5 OK created sql incremental model public.dim_product_descriptions ........ [[32mINSERT 0 637[0m in 0.39s]
[2023-09-21T09:31:28.317+0000] {subprocess.py:93} INFO - [0m09:31:28  2 of 5 START sql incremental model public.fct_product_prices ................... [RUN]
[2023-09-21T09:31:28.479+0000] {subprocess.py:93} INFO - [0m09:31:28  2 of 5 ERROR creating sql incremental model public.fct_product_prices .......... [[31mERROR[0m in 0.16s]
[2023-09-21T09:31:28.485+0000] {subprocess.py:93} INFO - [0m09:31:28  3 of 5 START sql incremental model public.fct_product_specials ................. [RUN]
[2023-09-21T09:31:28.645+0000] {subprocess.py:93} INFO - [0m09:31:28  3 of 5 OK created sql incremental model public.fct_product_specials ............ [[32mINSERT 0 199[0m in 0.16s]
[2023-09-21T09:31:28.651+0000] {subprocess.py:93} INFO - [0m09:31:28  4 of 5 SKIP relation public.mart_pricing_over_time ............................. [[33mSKIP[0m]
[2023-09-21T09:31:28.655+0000] {subprocess.py:93} INFO - [0m09:31:28  5 of 5 START sql incremental model public.mart_specials_over_time .............. [RUN]
[2023-09-21T09:31:28.812+0000] {subprocess.py:93} INFO - [0m09:31:28  5 of 5 OK created sql incremental model public.mart_specials_over_time ......... [[32mINSERT 0 199[0m in 0.15s]
[2023-09-21T09:31:28.841+0000] {subprocess.py:93} INFO - [0m09:31:28
[2023-09-21T09:31:28.842+0000] {subprocess.py:93} INFO - [0m09:31:28  Finished running 5 incremental models in 0 hours 0 minutes and 1.31 seconds (1.31s).
[2023-09-21T09:31:28.953+0000] {subprocess.py:93} INFO - [0m09:31:28
[2023-09-21T09:31:28.955+0000] {subprocess.py:93} INFO - [0m09:31:28  [31mCompleted with 1 error and 0 warnings:[0m
[2023-09-21T09:31:28.957+0000] {subprocess.py:93} INFO - [0m09:31:28
[2023-09-21T09:31:28.959+0000] {subprocess.py:93} INFO - [0m09:31:28  [33mDatabase Error in model fct_product_prices (models/fct_product_prices.sql)[0m
[2023-09-21T09:31:28.961+0000] {subprocess.py:93} INFO - [0m09:31:28    invalid input syntax for type numeric: ""
[2023-09-21T09:31:28.962+0000] {subprocess.py:93} INFO - [0m09:31:28    compiled Code at target/run/dbt_supermarket_data_engineering/models/fct_product_prices.sql
[2023-09-21T09:31:28.964+0000] {subprocess.py:93} INFO - [0m09:31:28
[2023-09-21T09:31:28.965+0000] {subprocess.py:93} INFO - [0m09:31:28  Done. PASS=3 WARN=0 ERROR=1 SKIP=1 TOTAL=5
[2023-09-21T09:31:30.771+0000] {subprocess.py:97} INFO - Command exited with return code 1
[2023-09-21T09:31:30.791+0000] {taskinstance.py:1935} ERROR - Task failed with exception
Traceback (most recent call last):
  File "/home/airflow/.local/lib/python3.8/site-packages/airflow/operators/bash.py", line 210, in execute
    raise AirflowException(
airflow.exceptions.AirflowException: Bash command failed. The command returned a non-zero exit code 1.
[2023-09-21T09:31:30.796+0000] {taskinstance.py:1398} INFO - Marking task as FAILED. dag_id=main_dag, task_id=run_dbt, execution_date=20230921T092949, start_date=20230921T093120, end_date=20230921T093130
[2023-09-21T09:31:30.828+0000] {standard_task_runner.py:104} ERROR - Failed to execute job 56 for task run_dbt (Bash command failed. The command returned a non-zero exit code 1.; 222)
[2023-09-21T09:31:30.875+0000] {local_task_job_runner.py:228} INFO - Task exited with return code 1
[2023-09-21T09:31:30.915+0000] {taskinstance.py:2776} INFO - 0 downstream tasks scheduled from follow-on schedule check
