[2023-09-23T13:51:43.624+0000] {taskinstance.py:1157} INFO - Dependencies all met for dep_context=non-requeueable deps ti=<TaskInstance: tests_dag.test_db_conns manual__2023-09-23T13:51:35.960843+00:00 [queued]>
[2023-09-23T13:51:43.641+0000] {taskinstance.py:1157} INFO - Dependencies all met for dep_context=requeueable deps ti=<TaskInstance: tests_dag.test_db_conns manual__2023-09-23T13:51:35.960843+00:00 [queued]>
[2023-09-23T13:51:43.641+0000] {taskinstance.py:1359} INFO - Starting attempt 1 of 1
[2023-09-23T13:51:43.666+0000] {taskinstance.py:1380} INFO - Executing <Task(BashOperator): test_db_conns> on 2023-09-23 13:51:35.960843+00:00
[2023-09-23T13:51:43.674+0000] {standard_task_runner.py:57} INFO - Started process 589 to run task
[2023-09-23T13:51:43.678+0000] {standard_task_runner.py:84} INFO - Running: ['***', 'tasks', 'run', 'tests_dag', 'test_db_conns', 'manual__2023-09-23T13:51:35.960843+00:00', '--job-id', '16', '--raw', '--subdir', 'DAGS_FOLDER/test_dag.py', '--cfg-path', '/tmp/tmpqzvqk9gg']
[2023-09-23T13:51:43.681+0000] {standard_task_runner.py:85} INFO - Job 16: Subtask test_db_conns
[2023-09-23T13:51:43.760+0000] {task_command.py:415} INFO - Running <TaskInstance: tests_dag.test_db_conns manual__2023-09-23T13:51:35.960843+00:00 [running]> on host 4ef300bfa8d2
[2023-09-23T13:51:43.927+0000] {taskinstance.py:1660} INFO - Exporting env vars: AIRFLOW_CTX_DAG_OWNER='***' AIRFLOW_CTX_DAG_ID='tests_dag' AIRFLOW_CTX_TASK_ID='test_db_conns' AIRFLOW_CTX_EXECUTION_DATE='2023-09-23T13:51:35.960843+00:00' AIRFLOW_CTX_TRY_NUMBER='1' AIRFLOW_CTX_DAG_RUN_ID='manual__2023-09-23T13:51:35.960843+00:00'
[2023-09-23T13:51:43.930+0000] {subprocess.py:63} INFO - Tmp dir root location: /tmp
[2023-09-23T13:51:43.931+0000] {subprocess.py:75} INFO - Running command: ['/bin/bash', '-c', 'pytest /opt/***/dags/dag_scripts/tests/test_db_connections.py']
[2023-09-23T13:51:43.946+0000] {subprocess.py:86} INFO - Output:
[2023-09-23T13:51:44.763+0000] {subprocess.py:93} INFO - ============================= test session starts ==============================
[2023-09-23T13:51:44.763+0000] {subprocess.py:93} INFO - platform linux -- Python 3.8.18, pytest-7.4.2, pluggy-1.3.0
[2023-09-23T13:51:44.763+0000] {subprocess.py:93} INFO - rootdir: /opt/***/dags/dag_scripts/tests
[2023-09-23T13:51:44.763+0000] {subprocess.py:93} INFO - plugins: anyio-4.0.0
[2023-09-23T13:51:44.764+0000] {subprocess.py:93} INFO - collected 0 items / 1 error
[2023-09-23T13:51:44.764+0000] {subprocess.py:93} INFO - 
[2023-09-23T13:51:44.764+0000] {subprocess.py:93} INFO - ==================================== ERRORS ====================================
[2023-09-23T13:51:44.764+0000] {subprocess.py:93} INFO - ___________________ ERROR collecting test_db_connections.py ____________________
[2023-09-23T13:51:44.764+0000] {subprocess.py:93} INFO - ImportError while importing test module '/opt/***/dags/dag_scripts/tests/test_db_connections.py'.
[2023-09-23T13:51:44.765+0000] {subprocess.py:93} INFO - Hint: make sure your test modules/packages have valid Python names.
[2023-09-23T13:51:44.765+0000] {subprocess.py:93} INFO - Traceback:
[2023-09-23T13:51:44.765+0000] {subprocess.py:93} INFO - /usr/local/lib/python3.8/importlib/__init__.py:127: in import_module
[2023-09-23T13:51:44.765+0000] {subprocess.py:93} INFO -     return _bootstrap._gcd_import(name[level:], package, level)
[2023-09-23T13:51:44.765+0000] {subprocess.py:93} INFO - /opt/***/dags/dag_scripts/tests/test_db_connections.py:6: in <module>
[2023-09-23T13:51:44.765+0000] {subprocess.py:93} INFO -     from dag_scripts.db_connections import db_connection_funcs
[2023-09-23T13:51:44.766+0000] {subprocess.py:93} INFO - E   ModuleNotFoundError: No module named 'dag_scripts'
[2023-09-23T13:51:44.766+0000] {subprocess.py:93} INFO - =============================== warnings summary ===============================
[2023-09-23T13:51:44.766+0000] {subprocess.py:93} INFO - ../../opt/***/dags/dag_scripts/tests/test_db_connections.py:63
[2023-09-23T13:51:44.766+0000] {subprocess.py:93} INFO -   /opt/***/dags/dag_scripts/tests/test_db_connections.py:63: PytestAssertRewriteWarning: assertion is always true, perhaps remove parentheses?
[2023-09-23T13:51:44.766+0000] {subprocess.py:93} INFO -     assert (response,True)
[2023-09-23T13:51:44.767+0000] {subprocess.py:93} INFO - 
[2023-09-23T13:51:44.767+0000] {subprocess.py:93} INFO - -- Docs: https://docs.pytest.org/en/stable/how-to/capture-warnings.html
[2023-09-23T13:51:44.767+0000] {subprocess.py:93} INFO - =========================== short test summary info ============================
[2023-09-23T13:51:44.767+0000] {subprocess.py:93} INFO - ERROR ../../opt/***/dags/dag_scripts/tests/test_db_connections.py
[2023-09-23T13:51:44.768+0000] {subprocess.py:93} INFO - !!!!!!!!!!!!!!!!!!!! Interrupted: 1 error during collection !!!!!!!!!!!!!!!!!!!!
[2023-09-23T13:51:44.768+0000] {subprocess.py:93} INFO - ========================= 1 warning, 1 error in 0.22s ==========================
[2023-09-23T13:51:44.817+0000] {subprocess.py:97} INFO - Command exited with return code 2
[2023-09-23T13:51:44.831+0000] {taskinstance.py:1935} ERROR - Task failed with exception
Traceback (most recent call last):
  File "/home/airflow/.local/lib/python3.8/site-packages/airflow/operators/bash.py", line 210, in execute
    raise AirflowException(
airflow.exceptions.AirflowException: Bash command failed. The command returned a non-zero exit code 2.
[2023-09-23T13:51:44.838+0000] {taskinstance.py:1398} INFO - Marking task as FAILED. dag_id=tests_dag, task_id=test_db_conns, execution_date=20230923T135135, start_date=20230923T135143, end_date=20230923T135144
[2023-09-23T13:51:44.873+0000] {standard_task_runner.py:104} ERROR - Failed to execute job 16 for task test_db_conns (Bash command failed. The command returned a non-zero exit code 2.; 589)
[2023-09-23T13:51:44.895+0000] {local_task_job_runner.py:228} INFO - Task exited with return code 1
[2023-09-23T13:51:44.932+0000] {taskinstance.py:2776} INFO - 0 downstream tasks scheduled from follow-on schedule check
