[2023-09-21T08:43:10.347+0000] {taskinstance.py:1157} INFO - Dependencies all met for dep_context=non-requeueable deps ti=<TaskInstance: main_dag.run_dbt manual__2023-09-21T08:41:38.110499+00:00 [queued]>
[2023-09-21T08:43:10.363+0000] {taskinstance.py:1157} INFO - Dependencies all met for dep_context=requeueable deps ti=<TaskInstance: main_dag.run_dbt manual__2023-09-21T08:41:38.110499+00:00 [queued]>
[2023-09-21T08:43:10.364+0000] {taskinstance.py:1359} INFO - Starting attempt 1 of 1
[2023-09-21T08:43:10.388+0000] {taskinstance.py:1380} INFO - Executing <Task(BashOperator): run_dbt> on 2023-09-21 08:41:38.110499+00:00
[2023-09-21T08:43:10.398+0000] {standard_task_runner.py:57} INFO - Started process 496 to run task
[2023-09-21T08:43:10.401+0000] {standard_task_runner.py:84} INFO - Running: ['***', 'tasks', 'run', 'main_dag', 'run_dbt', 'manual__2023-09-21T08:41:38.110499+00:00', '--job-id', '17', '--raw', '--subdir', 'DAGS_FOLDER/main_dag.py', '--cfg-path', '/tmp/tmpkujooifg']
[2023-09-21T08:43:10.405+0000] {standard_task_runner.py:85} INFO - Job 17: Subtask run_dbt
[2023-09-21T08:43:10.496+0000] {task_command.py:415} INFO - Running <TaskInstance: main_dag.run_dbt manual__2023-09-21T08:41:38.110499+00:00 [running]> on host efc7e3a30856
[2023-09-21T08:43:10.636+0000] {taskinstance.py:1660} INFO - Exporting env vars: AIRFLOW_CTX_DAG_OWNER='***' AIRFLOW_CTX_DAG_ID='main_dag' AIRFLOW_CTX_TASK_ID='run_dbt' AIRFLOW_CTX_EXECUTION_DATE='2023-09-21T08:41:38.110499+00:00' AIRFLOW_CTX_TRY_NUMBER='1' AIRFLOW_CTX_DAG_RUN_ID='manual__2023-09-21T08:41:38.110499+00:00'
[2023-09-21T08:43:10.639+0000] {subprocess.py:63} INFO - Tmp dir root location: /tmp
[2023-09-21T08:43:10.639+0000] {subprocess.py:75} INFO - Running command: ['/bin/bash', '-c', 'dbt run --profiles-dir /.dbt --project-dir /dbt_project']
[2023-09-21T08:43:10.655+0000] {subprocess.py:86} INFO - Output:
[2023-09-21T08:43:15.087+0000] {subprocess.py:93} INFO - [0m08:43:15  Running with dbt=1.5.3
[2023-09-21T08:43:15.335+0000] {subprocess.py:93} INFO - [0m08:43:15  Registered adapter: postgres=1.5.3
[2023-09-21T08:43:15.872+0000] {subprocess.py:93} INFO - [0m08:43:15  [[33mWARNING[0m]: Configuration paths exist in your dbt_project.yml file which do not apply to any resources.
[2023-09-21T08:43:15.874+0000] {subprocess.py:93} INFO - There are 1 unused configuration paths:
[2023-09-21T08:43:15.875+0000] {subprocess.py:93} INFO - - models.dbt_supermarket_data_engineering.example
[2023-09-21T08:43:15.930+0000] {subprocess.py:93} INFO - [0m08:43:15  Found 5 models, 0 tests, 1 snapshot, 0 analyses, 718 macros, 0 operations, 0 seed files, 1 source, 0 exposures, 0 metrics, 0 groups
[2023-09-21T08:43:15.934+0000] {subprocess.py:93} INFO - [0m08:43:15
[2023-09-21T08:43:16.290+0000] {subprocess.py:93} INFO - [0m08:43:16  Concurrency: 1 threads (target='dev')
[2023-09-21T08:43:16.293+0000] {subprocess.py:93} INFO - [0m08:43:16
[2023-09-21T08:43:16.312+0000] {subprocess.py:93} INFO - [0m08:43:16  1 of 5 START sql incremental model public.dim_product_descriptions ............. [RUN]
[2023-09-21T08:43:17.155+0000] {subprocess.py:93} INFO - [0m08:43:17  1 of 5 OK created sql incremental model public.dim_product_descriptions ........ [[32mINSERT 0 637[0m in 0.83s]
[2023-09-21T08:43:17.162+0000] {subprocess.py:93} INFO - [0m08:43:17  2 of 5 START sql incremental model public.fct_product_prices ................... [RUN]
[2023-09-21T08:43:17.489+0000] {subprocess.py:93} INFO - [0m08:43:17  2 of 5 ERROR creating sql incremental model public.fct_product_prices .......... [[31mERROR[0m in 0.32s]
[2023-09-21T08:43:17.495+0000] {subprocess.py:93} INFO - [0m08:43:17  3 of 5 START sql incremental model public.fct_product_specials ................. [RUN]
[2023-09-21T08:43:17.656+0000] {subprocess.py:93} INFO - [0m08:43:17  3 of 5 OK created sql incremental model public.fct_product_specials ............ [[32mINSERT 0 199[0m in 0.16s]
[2023-09-21T08:43:17.662+0000] {subprocess.py:93} INFO - [0m08:43:17  4 of 5 SKIP relation public.mart_pricing_over_time ............................. [[33mSKIP[0m]
[2023-09-21T08:43:17.666+0000] {subprocess.py:93} INFO - [0m08:43:17  5 of 5 START sql incremental model public.mart_specials_over_time .............. [RUN]
[2023-09-21T08:43:17.836+0000] {subprocess.py:93} INFO - [0m08:43:17  5 of 5 OK created sql incremental model public.mart_specials_over_time ......... [[32mINSERT 0 199[0m in 0.17s]
[2023-09-21T08:43:17.866+0000] {subprocess.py:93} INFO - [0m08:43:17
[2023-09-21T08:43:17.867+0000] {subprocess.py:93} INFO - [0m08:43:17  Finished running 5 incremental models in 0 hours 0 minutes and 1.93 seconds (1.93s).
[2023-09-21T08:43:17.947+0000] {subprocess.py:93} INFO - [0m08:43:17
[2023-09-21T08:43:17.948+0000] {subprocess.py:93} INFO - [0m08:43:17  [31mCompleted with 1 error and 0 warnings:[0m
[2023-09-21T08:43:17.949+0000] {subprocess.py:93} INFO - [0m08:43:17
[2023-09-21T08:43:17.951+0000] {subprocess.py:93} INFO - [0m08:43:17  [33mDatabase Error in model fct_product_prices (models/fct_product_prices.sql)[0m
[2023-09-21T08:43:17.952+0000] {subprocess.py:93} INFO - [0m08:43:17    invalid input syntax for type numeric: ""
[2023-09-21T08:43:17.953+0000] {subprocess.py:93} INFO - [0m08:43:17    compiled Code at target/run/dbt_supermarket_data_engineering/models/fct_product_prices.sql
[2023-09-21T08:43:17.954+0000] {subprocess.py:93} INFO - [0m08:43:17
[2023-09-21T08:43:17.957+0000] {subprocess.py:93} INFO - [0m08:43:17  Done. PASS=3 WARN=0 ERROR=1 SKIP=1 TOTAL=5
[2023-09-21T08:43:20.295+0000] {subprocess.py:97} INFO - Command exited with return code 1
[2023-09-21T08:43:20.312+0000] {taskinstance.py:1935} ERROR - Task failed with exception
Traceback (most recent call last):
  File "/home/airflow/.local/lib/python3.8/site-packages/airflow/operators/bash.py", line 210, in execute
    raise AirflowException(
airflow.exceptions.AirflowException: Bash command failed. The command returned a non-zero exit code 1.
[2023-09-21T08:43:20.317+0000] {taskinstance.py:1398} INFO - Marking task as FAILED. dag_id=main_dag, task_id=run_dbt, execution_date=20230921T084138, start_date=20230921T084310, end_date=20230921T084320
[2023-09-21T08:43:20.341+0000] {standard_task_runner.py:104} ERROR - Failed to execute job 17 for task run_dbt (Bash command failed. The command returned a non-zero exit code 1.; 496)
[2023-09-21T08:43:20.392+0000] {local_task_job_runner.py:228} INFO - Task exited with return code 1
[2023-09-21T08:43:20.443+0000] {taskinstance.py:2776} INFO - 0 downstream tasks scheduled from follow-on schedule check
