[2023-09-21T07:43:41.400+0000] {taskinstance.py:1157} INFO - Dependencies all met for dep_context=non-requeueable deps ti=<TaskInstance: main_dag.install_dbt_deps manual__2023-09-21T07:43:18.548925+00:00 [queued]>
[2023-09-21T07:43:41.433+0000] {taskinstance.py:1157} INFO - Dependencies all met for dep_context=requeueable deps ti=<TaskInstance: main_dag.install_dbt_deps manual__2023-09-21T07:43:18.548925+00:00 [queued]>
[2023-09-21T07:43:41.434+0000] {taskinstance.py:1359} INFO - Starting attempt 1 of 1
[2023-09-21T07:43:41.475+0000] {taskinstance.py:1380} INFO - Executing <Task(BashOperator): install_dbt_deps> on 2023-09-21 07:43:18.548925+00:00
[2023-09-21T07:43:41.488+0000] {standard_task_runner.py:57} INFO - Started process 93 to run task
[2023-09-21T07:43:41.497+0000] {standard_task_runner.py:84} INFO - Running: ['***', 'tasks', 'run', 'main_dag', 'install_dbt_deps', 'manual__2023-09-21T07:43:18.548925+00:00', '--job-id', '36', '--raw', '--subdir', 'DAGS_FOLDER/main_dag.py', '--cfg-path', '/tmp/tmphcdz0c_k']
[2023-09-21T07:43:41.941+0000] {standard_task_runner.py:85} INFO - Job 36: Subtask install_dbt_deps
[2023-09-21T07:43:42.082+0000] {task_command.py:415} INFO - Running <TaskInstance: main_dag.install_dbt_deps manual__2023-09-21T07:43:18.548925+00:00 [running]> on host a9cb98c10542
[2023-09-21T07:43:42.322+0000] {taskinstance.py:1660} INFO - Exporting env vars: AIRFLOW_CTX_DAG_OWNER='***' AIRFLOW_CTX_DAG_ID='main_dag' AIRFLOW_CTX_TASK_ID='install_dbt_deps' AIRFLOW_CTX_EXECUTION_DATE='2023-09-21T07:43:18.548925+00:00' AIRFLOW_CTX_TRY_NUMBER='1' AIRFLOW_CTX_DAG_RUN_ID='manual__2023-09-21T07:43:18.548925+00:00'
[2023-09-21T07:43:42.327+0000] {subprocess.py:63} INFO - Tmp dir root location: /tmp
[2023-09-21T07:43:42.329+0000] {subprocess.py:75} INFO - Running command: ['/bin/bash', '-c', 'dbt deps --profiles-dir /.dbt --project-dir /dbt_project']
[2023-09-21T07:43:42.362+0000] {subprocess.py:86} INFO - Output:
[2023-09-21T07:43:49.203+0000] {subprocess.py:93} INFO - [0m07:43:49  Encountered an error:
[2023-09-21T07:43:49.204+0000] {subprocess.py:93} INFO - [Errno 13] Permission denied: '/dbt_project/logs/dbt.log'
[2023-09-21T07:43:49.206+0000] {subprocess.py:93} INFO - [0m07:43:49  Traceback (most recent call last):
[2023-09-21T07:43:49.207+0000] {subprocess.py:93} INFO -   File "/home/***/.local/lib/python3.8/site-packages/dbt/cli/requires.py", line 86, in wrapper
[2023-09-21T07:43:49.207+0000] {subprocess.py:93} INFO -     result, success = func(*args, **kwargs)
[2023-09-21T07:43:49.208+0000] {subprocess.py:93} INFO -   File "/home/***/.local/lib/python3.8/site-packages/dbt/cli/requires.py", line 47, in wrapper
[2023-09-21T07:43:49.208+0000] {subprocess.py:93} INFO -     setup_event_logger(flags=flags, callbacks=callbacks)
[2023-09-21T07:43:49.208+0000] {subprocess.py:93} INFO -   File "/home/***/.local/lib/python3.8/site-packages/dbt/events/functions.py", line 64, in setup_event_logger
[2023-09-21T07:43:49.209+0000] {subprocess.py:93} INFO -     EVENT_MANAGER.add_logger(
[2023-09-21T07:43:49.209+0000] {subprocess.py:93} INFO -   File "/home/***/.local/lib/python3.8/site-packages/dbt/events/eventmgr.py", line 211, in add_logger
[2023-09-21T07:43:49.209+0000] {subprocess.py:93} INFO -     else _TextLogger(self, config)
[2023-09-21T07:43:49.209+0000] {subprocess.py:93} INFO -   File "/home/***/.local/lib/python3.8/site-packages/dbt/events/eventmgr.py", line 132, in __init__
[2023-09-21T07:43:49.210+0000] {subprocess.py:93} INFO -     super().__init__(event_manager, config)
[2023-09-21T07:43:49.210+0000] {subprocess.py:93} INFO -   File "/home/***/.local/lib/python3.8/site-packages/dbt/events/eventmgr.py", line 100, in __init__
[2023-09-21T07:43:49.210+0000] {subprocess.py:93} INFO -     file_handler = RotatingFileHandler(
[2023-09-21T07:43:49.210+0000] {subprocess.py:93} INFO -   File "/usr/local/lib/python3.8/logging/handlers.py", line 148, in __init__
[2023-09-21T07:43:49.211+0000] {subprocess.py:93} INFO -     BaseRotatingHandler.__init__(self, filename, mode, encoding, delay)
[2023-09-21T07:43:49.211+0000] {subprocess.py:93} INFO -   File "/usr/local/lib/python3.8/logging/handlers.py", line 55, in __init__
[2023-09-21T07:43:49.211+0000] {subprocess.py:93} INFO -     logging.FileHandler.__init__(self, filename, mode, encoding, delay)
[2023-09-21T07:43:49.211+0000] {subprocess.py:93} INFO -   File "/usr/local/lib/python3.8/logging/__init__.py", line 1147, in __init__
[2023-09-21T07:43:49.212+0000] {subprocess.py:93} INFO -     StreamHandler.__init__(self, self._open())
[2023-09-21T07:43:49.212+0000] {subprocess.py:93} INFO -   File "/usr/local/lib/python3.8/logging/__init__.py", line 1176, in _open
[2023-09-21T07:43:49.212+0000] {subprocess.py:93} INFO -     return open(self.baseFilename, self.mode, encoding=self.encoding)
[2023-09-21T07:43:49.212+0000] {subprocess.py:93} INFO - PermissionError: [Errno 13] Permission denied: '/dbt_project/logs/dbt.log'
[2023-09-21T07:43:49.213+0000] {subprocess.py:93} INFO - 
[2023-09-21T07:43:49.501+0000] {subprocess.py:97} INFO - Command exited with return code 2
[2023-09-21T07:43:49.549+0000] {taskinstance.py:1935} ERROR - Task failed with exception
Traceback (most recent call last):
  File "/home/airflow/.local/lib/python3.8/site-packages/airflow/operators/bash.py", line 210, in execute
    raise AirflowException(
airflow.exceptions.AirflowException: Bash command failed. The command returned a non-zero exit code 2.
[2023-09-21T07:43:49.559+0000] {taskinstance.py:1398} INFO - Marking task as FAILED. dag_id=main_dag, task_id=install_dbt_deps, execution_date=20230921T074318, start_date=20230921T074341, end_date=20230921T074349
[2023-09-21T07:43:49.889+0000] {standard_task_runner.py:104} ERROR - Failed to execute job 36 for task install_dbt_deps (Bash command failed. The command returned a non-zero exit code 2.; 93)
[2023-09-21T07:43:49.920+0000] {local_task_job_runner.py:228} INFO - Task exited with return code 1
[2023-09-21T07:43:50.110+0000] {taskinstance.py:2776} INFO - 0 downstream tasks scheduled from follow-on schedule check
