[2023-09-21T09:19:05.974+0000] {taskinstance.py:1157} INFO - Dependencies all met for dep_context=non-requeueable deps ti=<TaskInstance: main_dag.run_dbt manual__2023-09-21T09:17:11.211968+00:00 [queued]>
[2023-09-21T09:19:05.990+0000] {taskinstance.py:1157} INFO - Dependencies all met for dep_context=requeueable deps ti=<TaskInstance: main_dag.run_dbt manual__2023-09-21T09:17:11.211968+00:00 [queued]>
[2023-09-21T09:19:05.991+0000] {taskinstance.py:1359} INFO - Starting attempt 1 of 1
[2023-09-21T09:19:06.018+0000] {taskinstance.py:1380} INFO - Executing <Task(BashOperator): run_dbt> on 2023-09-21 09:17:11.211968+00:00
[2023-09-21T09:19:06.025+0000] {standard_task_runner.py:57} INFO - Started process 156 to run task
[2023-09-21T09:19:06.032+0000] {standard_task_runner.py:84} INFO - Running: ['***', 'tasks', 'run', 'main_dag', 'run_dbt', 'manual__2023-09-21T09:17:11.211968+00:00', '--job-id', '44', '--raw', '--subdir', 'DAGS_FOLDER/main_dag.py', '--cfg-path', '/tmp/tmpurok6t2e']
[2023-09-21T09:19:06.036+0000] {standard_task_runner.py:85} INFO - Job 44: Subtask run_dbt
[2023-09-21T09:19:06.125+0000] {task_command.py:415} INFO - Running <TaskInstance: main_dag.run_dbt manual__2023-09-21T09:17:11.211968+00:00 [running]> on host 96fb4b3e4632
[2023-09-21T09:19:06.291+0000] {taskinstance.py:1660} INFO - Exporting env vars: AIRFLOW_CTX_DAG_OWNER='***' AIRFLOW_CTX_DAG_ID='main_dag' AIRFLOW_CTX_TASK_ID='run_dbt' AIRFLOW_CTX_EXECUTION_DATE='2023-09-21T09:17:11.211968+00:00' AIRFLOW_CTX_TRY_NUMBER='1' AIRFLOW_CTX_DAG_RUN_ID='manual__2023-09-21T09:17:11.211968+00:00'
[2023-09-21T09:19:06.294+0000] {subprocess.py:63} INFO - Tmp dir root location: /tmp
[2023-09-21T09:19:06.296+0000] {subprocess.py:75} INFO - Running command: ['/bin/bash', '-c', 'dbt run --profiles-dir /.dbt --project-dir /dbt_project']
[2023-09-21T09:19:06.319+0000] {subprocess.py:86} INFO - Output:
[2023-09-21T09:19:10.927+0000] {subprocess.py:93} INFO - [0m09:19:10  Running with dbt=1.5.3
[2023-09-21T09:19:11.219+0000] {subprocess.py:93} INFO - [0m09:19:11  Registered adapter: postgres=1.5.3
[2023-09-21T09:19:11.802+0000] {subprocess.py:93} INFO - [0m09:19:11  [[33mWARNING[0m]: Configuration paths exist in your dbt_project.yml file which do not apply to any resources.
[2023-09-21T09:19:11.803+0000] {subprocess.py:93} INFO - There are 1 unused configuration paths:
[2023-09-21T09:19:11.803+0000] {subprocess.py:93} INFO - - models.dbt_supermarket_data_engineering.example
[2023-09-21T09:19:11.857+0000] {subprocess.py:93} INFO - [0m09:19:11  Found 5 models, 0 tests, 1 snapshot, 0 analyses, 718 macros, 0 operations, 0 seed files, 1 source, 0 exposures, 0 metrics, 0 groups
[2023-09-21T09:19:11.863+0000] {subprocess.py:93} INFO - [0m09:19:11
[2023-09-21T09:19:12.166+0000] {subprocess.py:93} INFO - [0m09:19:12  Concurrency: 1 threads (target='dev')
[2023-09-21T09:19:12.167+0000] {subprocess.py:93} INFO - [0m09:19:12
[2023-09-21T09:19:12.174+0000] {subprocess.py:93} INFO - [0m09:19:12  1 of 5 START sql incremental model public.dim_product_descriptions ............. [RUN]
[2023-09-21T09:19:12.815+0000] {subprocess.py:93} INFO - [0m09:19:12  1 of 5 OK created sql incremental model public.dim_product_descriptions ........ [[32mINSERT 0 637[0m in 0.64s]
[2023-09-21T09:19:12.820+0000] {subprocess.py:93} INFO - [0m09:19:12  2 of 5 START sql incremental model public.fct_product_prices ................... [RUN]
[2023-09-21T09:19:13.002+0000] {subprocess.py:93} INFO - [0m09:19:13  2 of 5 ERROR creating sql incremental model public.fct_product_prices .......... [[31mERROR[0m in 0.18s]
[2023-09-21T09:19:13.007+0000] {subprocess.py:93} INFO - [0m09:19:13  3 of 5 START sql incremental model public.fct_product_specials ................. [RUN]
[2023-09-21T09:19:13.246+0000] {subprocess.py:93} INFO - [0m09:19:13  3 of 5 OK created sql incremental model public.fct_product_specials ............ [[32mINSERT 0 199[0m in 0.23s]
[2023-09-21T09:19:13.253+0000] {subprocess.py:93} INFO - [0m09:19:13  4 of 5 SKIP relation public.mart_pricing_over_time ............................. [[33mSKIP[0m]
[2023-09-21T09:19:13.269+0000] {subprocess.py:93} INFO - [0m09:19:13  5 of 5 START sql incremental model public.mart_specials_over_time .............. [RUN]
[2023-09-21T09:19:13.609+0000] {subprocess.py:93} INFO - [0m09:19:13  5 of 5 OK created sql incremental model public.mart_specials_over_time ......... [[32mINSERT 0 199[0m in 0.34s]
[2023-09-21T09:19:13.639+0000] {subprocess.py:93} INFO - [0m09:19:13
[2023-09-21T09:19:13.640+0000] {subprocess.py:93} INFO - [0m09:19:13  Finished running 5 incremental models in 0 hours 0 minutes and 1.77 seconds (1.77s).
[2023-09-21T09:19:13.733+0000] {subprocess.py:93} INFO - [0m09:19:13
[2023-09-21T09:19:13.735+0000] {subprocess.py:93} INFO - [0m09:19:13  [31mCompleted with 1 error and 0 warnings:[0m
[2023-09-21T09:19:13.736+0000] {subprocess.py:93} INFO - [0m09:19:13
[2023-09-21T09:19:13.737+0000] {subprocess.py:93} INFO - [0m09:19:13  [33mDatabase Error in model fct_product_prices (models/fct_product_prices.sql)[0m
[2023-09-21T09:19:13.738+0000] {subprocess.py:93} INFO - [0m09:19:13    invalid input syntax for type numeric: ""
[2023-09-21T09:19:13.739+0000] {subprocess.py:93} INFO - [0m09:19:13    compiled Code at target/run/dbt_supermarket_data_engineering/models/fct_product_prices.sql
[2023-09-21T09:19:13.740+0000] {subprocess.py:93} INFO - [0m09:19:13
[2023-09-21T09:19:13.742+0000] {subprocess.py:93} INFO - [0m09:19:13  Done. PASS=3 WARN=0 ERROR=1 SKIP=1 TOTAL=5
[2023-09-21T09:19:15.569+0000] {subprocess.py:97} INFO - Command exited with return code 1
[2023-09-21T09:19:15.586+0000] {taskinstance.py:1935} ERROR - Task failed with exception
Traceback (most recent call last):
  File "/home/airflow/.local/lib/python3.8/site-packages/airflow/operators/bash.py", line 210, in execute
    raise AirflowException(
airflow.exceptions.AirflowException: Bash command failed. The command returned a non-zero exit code 1.
[2023-09-21T09:19:15.591+0000] {taskinstance.py:1398} INFO - Marking task as FAILED. dag_id=main_dag, task_id=run_dbt, execution_date=20230921T091711, start_date=20230921T091905, end_date=20230921T091915
[2023-09-21T09:19:15.628+0000] {standard_task_runner.py:104} ERROR - Failed to execute job 44 for task run_dbt (Bash command failed. The command returned a non-zero exit code 1.; 156)
[2023-09-21T09:19:15.662+0000] {local_task_job_runner.py:228} INFO - Task exited with return code 1
[2023-09-21T09:19:15.708+0000] {taskinstance.py:2776} INFO - 0 downstream tasks scheduled from follow-on schedule check
