[2023-09-21T09:29:04.721+0000] {taskinstance.py:1157} INFO - Dependencies all met for dep_context=non-requeueable deps ti=<TaskInstance: main_dag.run_dbt manual__2023-09-21T09:27:26.111868+00:00 [queued]>
[2023-09-21T09:29:04.736+0000] {taskinstance.py:1157} INFO - Dependencies all met for dep_context=requeueable deps ti=<TaskInstance: main_dag.run_dbt manual__2023-09-21T09:27:26.111868+00:00 [queued]>
[2023-09-21T09:29:04.737+0000] {taskinstance.py:1359} INFO - Starting attempt 1 of 1
[2023-09-21T09:29:04.761+0000] {taskinstance.py:1380} INFO - Executing <Task(BashOperator): run_dbt> on 2023-09-21 09:27:26.111868+00:00
[2023-09-21T09:29:04.770+0000] {standard_task_runner.py:57} INFO - Started process 157 to run task
[2023-09-21T09:29:04.774+0000] {standard_task_runner.py:84} INFO - Running: ['***', 'tasks', 'run', 'main_dag', 'run_dbt', 'manual__2023-09-21T09:27:26.111868+00:00', '--job-id', '51', '--raw', '--subdir', 'DAGS_FOLDER/main_dag.py', '--cfg-path', '/tmp/tmp45ocy54f']
[2023-09-21T09:29:04.777+0000] {standard_task_runner.py:85} INFO - Job 51: Subtask run_dbt
[2023-09-21T09:29:04.854+0000] {task_command.py:415} INFO - Running <TaskInstance: main_dag.run_dbt manual__2023-09-21T09:27:26.111868+00:00 [running]> on host 657a599f4719
[2023-09-21T09:29:04.975+0000] {taskinstance.py:1660} INFO - Exporting env vars: AIRFLOW_CTX_DAG_OWNER='***' AIRFLOW_CTX_DAG_ID='main_dag' AIRFLOW_CTX_TASK_ID='run_dbt' AIRFLOW_CTX_EXECUTION_DATE='2023-09-21T09:27:26.111868+00:00' AIRFLOW_CTX_TRY_NUMBER='1' AIRFLOW_CTX_DAG_RUN_ID='manual__2023-09-21T09:27:26.111868+00:00'
[2023-09-21T09:29:04.978+0000] {subprocess.py:63} INFO - Tmp dir root location: /tmp
[2023-09-21T09:29:04.979+0000] {subprocess.py:75} INFO - Running command: ['/bin/bash', '-c', 'dbt run --profiles-dir /.dbt --project-dir /dbt_project']
[2023-09-21T09:29:04.995+0000] {subprocess.py:86} INFO - Output:
[2023-09-21T09:29:09.359+0000] {subprocess.py:93} INFO - [0m09:29:09  Running with dbt=1.5.3
[2023-09-21T09:29:09.774+0000] {subprocess.py:93} INFO - [0m09:29:09  Registered adapter: postgres=1.5.3
[2023-09-21T09:29:10.466+0000] {subprocess.py:93} INFO - [0m09:29:10  [[33mWARNING[0m]: Configuration paths exist in your dbt_project.yml file which do not apply to any resources.
[2023-09-21T09:29:10.467+0000] {subprocess.py:93} INFO - There are 1 unused configuration paths:
[2023-09-21T09:29:10.467+0000] {subprocess.py:93} INFO - - models.dbt_supermarket_data_engineering.example
[2023-09-21T09:29:10.510+0000] {subprocess.py:93} INFO - [0m09:29:10  Found 5 models, 0 tests, 1 snapshot, 0 analyses, 718 macros, 0 operations, 0 seed files, 1 source, 0 exposures, 0 metrics, 0 groups
[2023-09-21T09:29:10.517+0000] {subprocess.py:93} INFO - [0m09:29:10
[2023-09-21T09:29:10.839+0000] {subprocess.py:93} INFO - [0m09:29:10  Concurrency: 1 threads (target='dev')
[2023-09-21T09:29:10.840+0000] {subprocess.py:93} INFO - [0m09:29:10
[2023-09-21T09:29:10.848+0000] {subprocess.py:93} INFO - [0m09:29:10  1 of 5 START sql incremental model public.dim_product_descriptions ............. [RUN]
[2023-09-21T09:29:11.412+0000] {subprocess.py:93} INFO - [0m09:29:11  1 of 5 OK created sql incremental model public.dim_product_descriptions ........ [[32mINSERT 0 637[0m in 0.56s]
[2023-09-21T09:29:11.418+0000] {subprocess.py:93} INFO - [0m09:29:11  2 of 5 START sql incremental model public.fct_product_prices ................... [RUN]
[2023-09-21T09:29:11.483+0000] {subprocess.py:93} INFO - [0m09:29:11  2 of 5 ERROR creating sql incremental model public.fct_product_prices .......... [[31mERROR[0m in 0.06s]
[2023-09-21T09:29:11.486+0000] {subprocess.py:93} INFO - [0m09:29:11  3 of 5 START sql incremental model public.fct_product_specials ................. [RUN]
[2023-09-21T09:29:11.690+0000] {subprocess.py:93} INFO - [0m09:29:11  3 of 5 OK created sql incremental model public.fct_product_specials ............ [[32mINSERT 0 199[0m in 0.20s]
[2023-09-21T09:29:11.694+0000] {subprocess.py:93} INFO - [0m09:29:11  4 of 5 SKIP relation public.mart_pricing_over_time ............................. [[33mSKIP[0m]
[2023-09-21T09:29:11.699+0000] {subprocess.py:93} INFO - [0m09:29:11  5 of 5 START sql incremental model public.mart_specials_over_time .............. [RUN]
[2023-09-21T09:29:11.924+0000] {subprocess.py:93} INFO - [0m09:29:11  5 of 5 OK created sql incremental model public.mart_specials_over_time ......... [[32mINSERT 0 199[0m in 0.22s]
[2023-09-21T09:29:11.952+0000] {subprocess.py:93} INFO - [0m09:29:11
[2023-09-21T09:29:11.953+0000] {subprocess.py:93} INFO - [0m09:29:11  Finished running 5 incremental models in 0 hours 0 minutes and 1.43 seconds (1.43s).
[2023-09-21T09:29:12.027+0000] {subprocess.py:93} INFO - [0m09:29:12
[2023-09-21T09:29:12.029+0000] {subprocess.py:93} INFO - [0m09:29:12  [31mCompleted with 1 error and 0 warnings:[0m
[2023-09-21T09:29:12.031+0000] {subprocess.py:93} INFO - [0m09:29:12
[2023-09-21T09:29:12.033+0000] {subprocess.py:93} INFO - [0m09:29:12  [33mDatabase Error in model fct_product_prices (models/fct_product_prices.sql)[0m
[2023-09-21T09:29:12.034+0000] {subprocess.py:93} INFO - [0m09:29:12    syntax error at or near ":"
[2023-09-21T09:29:12.035+0000] {subprocess.py:93} INFO - [0m09:29:12    LINE 32:         WHEN size IS NULL THEN null:numeric
[2023-09-21T09:29:12.036+0000] {subprocess.py:93} INFO - [0m09:29:12                                                ^
[2023-09-21T09:29:12.037+0000] {subprocess.py:93} INFO - [0m09:29:12    compiled Code at target/run/dbt_supermarket_data_engineering/models/fct_product_prices.sql
[2023-09-21T09:29:12.038+0000] {subprocess.py:93} INFO - [0m09:29:12
[2023-09-21T09:29:12.039+0000] {subprocess.py:93} INFO - [0m09:29:12  Done. PASS=3 WARN=0 ERROR=1 SKIP=1 TOTAL=5
[2023-09-21T09:29:14.405+0000] {subprocess.py:97} INFO - Command exited with return code 1
[2023-09-21T09:29:14.437+0000] {taskinstance.py:1935} ERROR - Task failed with exception
Traceback (most recent call last):
  File "/home/airflow/.local/lib/python3.8/site-packages/airflow/operators/bash.py", line 210, in execute
    raise AirflowException(
airflow.exceptions.AirflowException: Bash command failed. The command returned a non-zero exit code 1.
[2023-09-21T09:29:14.451+0000] {taskinstance.py:1398} INFO - Marking task as FAILED. dag_id=main_dag, task_id=run_dbt, execution_date=20230921T092726, start_date=20230921T092904, end_date=20230921T092914
[2023-09-21T09:29:14.504+0000] {standard_task_runner.py:104} ERROR - Failed to execute job 51 for task run_dbt (Bash command failed. The command returned a non-zero exit code 1.; 157)
[2023-09-21T09:29:14.547+0000] {local_task_job_runner.py:228} INFO - Task exited with return code 1
[2023-09-21T09:29:14.623+0000] {taskinstance.py:2776} INFO - 0 downstream tasks scheduled from follow-on schedule check
