[2023-09-20T09:58:41.223+0000] {taskinstance.py:1157} INFO - Dependencies all met for dep_context=non-requeueable deps ti=<TaskInstance: main_dag.clear_mongodb manual__2023-09-20T09:58:36.046097+00:00 [queued]>
[2023-09-20T09:58:41.241+0000] {taskinstance.py:1157} INFO - Dependencies all met for dep_context=requeueable deps ti=<TaskInstance: main_dag.clear_mongodb manual__2023-09-20T09:58:36.046097+00:00 [queued]>
[2023-09-20T09:58:41.242+0000] {taskinstance.py:1359} INFO - Starting attempt 1 of 1
[2023-09-20T09:58:41.284+0000] {taskinstance.py:1380} INFO - Executing <Task(PythonOperator): clear_mongodb> on 2023-09-20 09:58:36.046097+00:00
[2023-09-20T09:58:41.295+0000] {standard_task_runner.py:57} INFO - Started process 123 to run task
[2023-09-20T09:58:41.303+0000] {standard_task_runner.py:84} INFO - Running: ['***', 'tasks', 'run', 'main_dag', 'clear_mongodb', 'manual__2023-09-20T09:58:36.046097+00:00', '--job-id', '12', '--raw', '--subdir', 'DAGS_FOLDER/main_dag.py', '--cfg-path', '/tmp/tmps7yit1fq']
[2023-09-20T09:58:41.309+0000] {standard_task_runner.py:85} INFO - Job 12: Subtask clear_mongodb
[2023-09-20T09:58:41.423+0000] {task_command.py:415} INFO - Running <TaskInstance: main_dag.clear_mongodb manual__2023-09-20T09:58:36.046097+00:00 [running]> on host fb50cb700c4d
[2023-09-20T09:58:41.640+0000] {taskinstance.py:1660} INFO - Exporting env vars: AIRFLOW_CTX_DAG_OWNER='***' AIRFLOW_CTX_DAG_ID='main_dag' AIRFLOW_CTX_TASK_ID='clear_mongodb' AIRFLOW_CTX_EXECUTION_DATE='2023-09-20T09:58:36.046097+00:00' AIRFLOW_CTX_TRY_NUMBER='1' AIRFLOW_CTX_DAG_RUN_ID='manual__2023-09-20T09:58:36.046097+00:00'
[2023-09-20T09:59:11.860+0000] {taskinstance.py:1935} ERROR - Task failed with exception
Traceback (most recent call last):
  File "/home/airflow/.local/lib/python3.8/site-packages/airflow/operators/python.py", line 192, in execute
    return_value = self.execute_callable()
  File "/home/airflow/.local/lib/python3.8/site-packages/airflow/operators/python.py", line 209, in execute_callable
    return self.python_callable(*self.op_args, **self.op_kwargs)
  File "/opt/airflow/dags/dag_scripts/clear_mongodb_staging.py", line 13, in main
    mongodb_collection.delete_many({})
  File "/home/airflow/.local/lib/python3.8/site-packages/pymongo/collection.py", line 1426, in delete_many
    self._delete_retryable(
  File "/home/airflow/.local/lib/python3.8/site-packages/pymongo/collection.py", line 1301, in _delete_retryable
    return self.__database.client._retryable_write(
  File "/home/airflow/.local/lib/python3.8/site-packages/pymongo/mongo_client.py", line 1492, in _retryable_write
    with self._tmp_session(session) as s:
  File "/usr/local/lib/python3.8/contextlib.py", line 113, in __enter__
    return next(self.gen)
  File "/home/airflow/.local/lib/python3.8/site-packages/pymongo/mongo_client.py", line 1775, in _tmp_session
    s = self._ensure_session(session)
  File "/home/airflow/.local/lib/python3.8/site-packages/pymongo/mongo_client.py", line 1758, in _ensure_session
    return self.__start_session(True, causal_consistency=False)
  File "/home/airflow/.local/lib/python3.8/site-packages/pymongo/mongo_client.py", line 1703, in __start_session
    self._topology._check_implicit_session_support()
  File "/home/airflow/.local/lib/python3.8/site-packages/pymongo/topology.py", line 538, in _check_implicit_session_support
    self._check_session_support()
  File "/home/airflow/.local/lib/python3.8/site-packages/pymongo/topology.py", line 554, in _check_session_support
    self._select_servers_loop(
  File "/home/airflow/.local/lib/python3.8/site-packages/pymongo/topology.py", line 238, in _select_servers_loop
    raise ServerSelectionTimeoutError(
pymongo.errors.ServerSelectionTimeoutError: mongodb:27018: [Errno 111] Connection refused, Timeout: 30s, Topology Description: <TopologyDescription id: 650ac251e312afea995fea9a, topology_type: Unknown, servers: [<ServerDescription ('mongodb', 27018) server_type: Unknown, rtt: None, error=AutoReconnect('mongodb:27018: [Errno 111] Connection refused')>]>
[2023-09-20T09:59:11.892+0000] {taskinstance.py:1398} INFO - Marking task as FAILED. dag_id=main_dag, task_id=clear_mongodb, execution_date=20230920T095836, start_date=20230920T095841, end_date=20230920T095911
[2023-09-20T09:59:11.930+0000] {standard_task_runner.py:104} ERROR - Failed to execute job 12 for task clear_mongodb (mongodb:27018: [Errno 111] Connection refused, Timeout: 30s, Topology Description: <TopologyDescription id: 650ac251e312afea995fea9a, topology_type: Unknown, servers: [<ServerDescription ('mongodb', 27018) server_type: Unknown, rtt: None, error=AutoReconnect('mongodb:27018: [Errno 111] Connection refused')>]>; 123)
[2023-09-20T09:59:11.975+0000] {local_task_job_runner.py:228} INFO - Task exited with return code 1
[2023-09-20T09:59:12.042+0000] {taskinstance.py:2776} INFO - 0 downstream tasks scheduled from follow-on schedule check
