[2023-09-23T13:27:38.080+0000] {taskinstance.py:1157} INFO - Dependencies all met for dep_context=non-requeueable deps ti=<TaskInstance: tests_dag.test_imports scheduled__2023-09-21T16:00:00+00:00 [queued]>
[2023-09-23T13:27:38.139+0000] {taskinstance.py:1157} INFO - Dependencies all met for dep_context=requeueable deps ti=<TaskInstance: tests_dag.test_imports scheduled__2023-09-21T16:00:00+00:00 [queued]>
[2023-09-23T13:27:38.139+0000] {taskinstance.py:1359} INFO - Starting attempt 1 of 1
[2023-09-23T13:27:38.251+0000] {taskinstance.py:1380} INFO - Executing <Task(BashOperator): test_imports> on 2023-09-21 16:00:00+00:00
[2023-09-23T13:27:38.259+0000] {standard_task_runner.py:57} INFO - Started process 123 to run task
[2023-09-23T13:27:38.265+0000] {standard_task_runner.py:84} INFO - Running: ['***', 'tasks', 'run', 'tests_dag', 'test_imports', 'scheduled__2023-09-21T16:00:00+00:00', '--job-id', '3', '--raw', '--subdir', 'DAGS_FOLDER/test_dag.py', '--cfg-path', '/tmp/tmpao3a1ufv']
[2023-09-23T13:27:38.273+0000] {standard_task_runner.py:85} INFO - Job 3: Subtask test_imports
[2023-09-23T13:27:38.510+0000] {task_command.py:415} INFO - Running <TaskInstance: tests_dag.test_imports scheduled__2023-09-21T16:00:00+00:00 [running]> on host 4ef300bfa8d2
[2023-09-23T13:27:38.938+0000] {taskinstance.py:1660} INFO - Exporting env vars: AIRFLOW_CTX_DAG_OWNER='***' AIRFLOW_CTX_DAG_ID='tests_dag' AIRFLOW_CTX_TASK_ID='test_imports' AIRFLOW_CTX_EXECUTION_DATE='2023-09-21T16:00:00+00:00' AIRFLOW_CTX_TRY_NUMBER='1' AIRFLOW_CTX_DAG_RUN_ID='scheduled__2023-09-21T16:00:00+00:00'
[2023-09-23T13:27:38.944+0000] {subprocess.py:63} INFO - Tmp dir root location: /tmp
[2023-09-23T13:27:38.955+0000] {subprocess.py:75} INFO - Running command: ['/bin/bash', '-c', 'pytest /opt/***/dags/dag_scripts/tests/test_imports.py > /opt/***/dags/dag_scripts/tests/test_imports.log']
[2023-09-23T13:27:39.006+0000] {subprocess.py:86} INFO - Output:
[2023-09-23T13:27:49.338+0000] {subprocess.py:97} INFO - Command exited with return code 1
[2023-09-23T13:27:49.351+0000] {taskinstance.py:1935} ERROR - Task failed with exception
Traceback (most recent call last):
  File "/home/airflow/.local/lib/python3.8/site-packages/airflow/operators/bash.py", line 210, in execute
    raise AirflowException(
airflow.exceptions.AirflowException: Bash command failed. The command returned a non-zero exit code 1.
[2023-09-23T13:27:49.355+0000] {taskinstance.py:1398} INFO - Marking task as FAILED. dag_id=tests_dag, task_id=test_imports, execution_date=20230921T160000, start_date=20230923T132738, end_date=20230923T132749
[2023-09-23T13:27:49.394+0000] {standard_task_runner.py:104} ERROR - Failed to execute job 3 for task test_imports (Bash command failed. The command returned a non-zero exit code 1.; 123)
[2023-09-23T13:27:49.409+0000] {local_task_job_runner.py:228} INFO - Task exited with return code 1
[2023-09-23T13:27:49.443+0000] {taskinstance.py:2776} INFO - 0 downstream tasks scheduled from follow-on schedule check
